Workbook

Sheet informe de Gestión 2021-2025
A1: Nº | B1: Nº | C1: LOCALIDAD | D1: DEPARTAMENTO | E1: BANDA | F1: FREC. | G1: POTENCIA | H1: ESTADO | I1: SITUACIÓN DE LA LICENCIA | J1: RVM | K1: FECHA DE VENCIMIENTO
A2: 48 | B2: 4 | C2: Barranca | D2: Lima | E2: FM | F2: 97.5 | G2: 950 | H2: AL AIRE | I2: Asociación Cultural Bethel | J2: RVM Nº 1150-2016-MTC/03 | K2: 45730
A3: 61 | B3: 6 | C3: Camaná | D3: Arequipa | E3: FM | F3: 91.7 | G3: 100 | H3: AL AIRE | I3: Asociación Cultural Bethel | J3: RVM Nº 473-2015-MTC/03 | K3: 45741
A4: =A3+1 -> 62 | B4: 28 | C4: Moyobamba | D4: San Martin | E4: FM | F4: 94.5 | G4: 950 | H4: AL AIRE | I4: Asociación Cultural Bethel | J4: RVM Nº 427-2015-MTC/03 | K4: 45742
A5: 101 | B5: 10 | C5: Chinchero | D5: Cusco | E5: VHF | F5: 10 | G5: 50 | H5: AL AIRE | I5: Asociación Cultural Bethel | J5: RVM N° 163-2015-MTC/03 | K5: 45781
A6: 65 | B6: 8 | C6: Candarave | D6: Tacna | E6: FM | F6: 97.5 | G6: 50 | H6: AL AIRE | I6: Asociación Cultural Bethel | J6: RVM N° 170-2015-MTC/03 | K6: 45788
A7: 54 | B7: 5 | C7: Cabanilla | D7: Puno | E7: FM | F7: 89.3 | G7: 50 | H7: AL AIRE | I7: Asociación Cultural Bethel | J7: RVM Nº 757-2015-MTC/03 | K7: 45841
A8: 107 | B8: 12 | C8: Chosica - Lurigancho | D8: Lima | E8: FM | F8: 97.7 | G8: 250 | H8: AL AIRE | I8: Asociación Cultural Bethel | J8: RVM Nº 303-95-MTC/15.17 | K8: 45848
A9: =A8+1 -> 108 | B9: 27 | C9: Mollendo | D9: Arequipa | E9: FM | F9: 93.1 | G9: 250 | H9: AL AIRE | I9: Radio Oasis S. C R. L. | J9: RM Nº 300-95-MTC | K9: 45848
A10: =A9+1 -> 109 | B10: 14 | C10: Huancayo | D10: Junin | E10: AM | F10: 1050 | G10: 740 | H10: AL AIRE | I10: Asociación Cultural Bethel | J10: RVM Nº 064-2016-MTC/03 | K10: 45855
A11: =A10+1 -> 110 | B11: 41 | C11: Tocache | D11: San Martin | E11: FM | F11: 95.7 | G11: 500 | H11: AL AIRE | I11: Asociación Cultural Bethel | J11: RVM Nº 404-2005-MTC/03 | K11: 45871
A12: =A11+1 -> 111 | B12: 37 | C12: Ranracancha | D12: Apurimac | E12: FM | F12: 97.1 | G12: 50 | H12: AL AIRE | I12: Asociación Cultural Bethel | J12: RVM N° 311-2015-MTC/03 | K12: 45879
A13: =A12+1 -> 112 | B13: 29 | C13: Nazca | D13: Ica | E13: FM | F13: 95.9 | G13: 250 | H13: AL AIRE | I13: Asociación Cultural Bethel | J13: RVM Nº 419-2005-MTC/03 | K13: 45892
A14: =A13+1 -> 113 | B14: 16 | C14: Huayllay | D14: Pasco | E14: FM | F14: 94.1 | G14: 130 | H14: AL AIRE | I14: PROCESO DE TRAMITE DE TRANSFERENCIA | J14: RVM N° 366-2015-MTC/03 | K14: 45895
A15: =A14+1 -> 114 | B15: 17 | C15: Huaynacotas | D15: Arequipa | E15: FM | F15: 106.3 | G15: 250 | H15: AL AIRE | I15: Asociación Cultural Bethel | J15: RVM N° 387-2015-MTC/03 | K15: 45900
A16: =A15+1 -> 115 | B16: 35 | C16: Pedregal - Majes | D16: Arequipa | E16: VHF | F16: 4 | G16: 500 | H16: AL AIRE | I16: Asociación Cultural Bethel | J16: RVM Nº 115-2016-MTC/03 | K16: 45901
A17: =A16+1 -> 116 | B17: 22 | C17: La Arena | D17: Piura | E17: FM | F17: 106.9 | G17: 100 | H17: AL AIRE | I17: Asociación Cultural Bethel | J17: RVM Nº 1137-2016-MTC/ 03 | K17: 45908
A18: =A17+1 -> 117 | B18: 40 | C18: Santa Rosa | D18: Ayacucho | E18: VHF | F18: 12 | G18: 50 | H18: AL AIRE | I18: Victor Arispe Qwistgaard | J18: RVM N° 420-2015-MTC/03 | K18: 45908
A19: 105 | B19: 11 | C19: Chivay | D19: Arequipa | E19: FM | F19: 93.3 | G19: 250 | H19: AL AIRE | I19: Asociación Cultural Bethel | J19: RVM N° 437-2015-MTC/03 | K19: 45909
A20: =A19+1 -> 106 | B20: 19 | C20: Jaen | D20: Cajamarca | E20: FM | F20: 100.5 | G20: 950 | H20: AL AIRE | I20: Asociación Cultural Bethel | J20: RVM Nº 583-2015-MTC/03 | K20: 45909
A21: 2 | B21: 1 | C21: Abancay - Tamburco | D21: Apurimac | E21: UHF | F21: 33 | G21: 50 | H21: AL AIRE | I21: Asociación Cultural Bethel | J21: RVM Nº 116-2016-MTC/03 | K21: 45929
A22: 125 | B22: 13 | C22: Curahuasi | D22: Apurimac | E22: VHF | F22: 9 | G22: 50 | H22: AL AIRE | I22: Victor Arispe Qwistgaard | J22: RVM N° 523-2015-MTC/03 | K22: 45932
A23: =A22+1 -> 126 | B23: 36 | C23: Piscobamba | D23: Ancash | E23: FM | F23: 97.9 | G23: 250 | H23: AL AIRE | I23: PROCESO DE TRAMITE DE TRANSFERENCIA | J23: RVM N° 566-2015-MTC/03 | K23: 45946
A24: =A23+1 -> 127 | B24: 21 | C24: Kepashiato | D24: Cusco | E24: FM | F24: 95.5 | G24: 50 | H24: AL AIRE | I24: Asociación Cultural Bethel | J24: RVM N° 589-2015-MTC/03 | K24: 45953
A25: 46 | B25: 3 | C25: Bambamarca | D25: Cajamarca | E25: FM | F25: 89.7 | G25: 250 | H25: AL AIRE | I25: Asociación Cultural Bethel | J25: RVM N° 606-2015-MTC/03 | K25: 45957
A26: =A25+1 -> 47 | B26: 38 | C26: Requena | D26: Loreto | E26: FM | F26: 96.7 | G26: 500 | H26: AL AIRE | I26: Asociación Cultural Bethel | J26: RVM N° 604-2015-MTC/03 | K26: 45957
A27: =A26+1 -> 48 | B27: 30 | C27: Nepeña | D27: Ancash | E27: FM | F27: 104.7 | G27: 250 | H27: AL AIRE | I27: PROCESO DE TRAMITE DE TRANSFERENCIA | J27: RVM N° 573-2015-MTC/03 | K27: 45958
A28: =A27+1 -> 49 | B28: 23 | C28: Lima | D28: Lima | E28: FM | F28: 100.1 | G28: 20000 | H28: AL AIRE | I28: Lima Cien Stereo S.A.C. | J28: RVM Nº 604-2001-MTC/15.03 | K28: 45964
A29: =A28+1 -> 50 | B29: 18 | C29: Ilave | D29: Puno | E29: FM | F29: 97.3 | G29: 250 | H29: AL AIRE | I29: Asociación Cultural Bethel | J29: RVM Nº 1101-2016-MTC/03 | K29: 45979
A30: 63 | B30: 7 | C30: Campanilla | D30: San Martin | E30: FM | F30: 91.7 | G30: 150 | H30: AL AIRE | I30: Victor Arispe Qwistgaard | J30: RVM N° 684-2015-MTC/03 | K30: 45980
A31: =A30+1 -> 64 | B31: 31 | C31: Olleros | D31: Ancash | E31: VHF | F31: 12 | G31: 200 | H31: FUERA AL AIRE | I31: Asociación Cultural Bethel | J31: RVM N° 732-2015-MTC/03 | K31: 45992
A32: 17 | B32: 2 | C32: Andajes | D32: Lima | E32: FM | F32: 103.1 | G32: 50 | H32: AL AIRE | I32: Asociación Cultural Bethel | J32: RVM Nº 795-2015-MTC/03 | K32: 46002
A33: =A32+1 -> 18 | B33: 32 | C33: Pacucha | D33: Apurimac | E33: FM | F33: 96.5 | G33: 50 | H33: AL AIRE | I33: Milciades Edgardo Narro Pretell | J33: RVM N° 802-2015-MTC/03 | K33: 46002
A34: =A33+1 -> 19 | B34: 15 | C34: Huasahuasi | D34: Junin | E34: FM | F34: 100.5 | G34: 250 | H34: AL AIRE | I34: Asociación Cultural Bethel | J34: RVM Nº 866-2015-MTC/03 | K34: 46015
A35: =A34+1 -> 20 | B35: 20 | C35: Kaquiabamba | D35: Apurimac | E35: FM | F35: 93.7 | G35: 50 | H35: AL AIRE | I35: Milciades Edgardo Narro Pretell | J35: RVM N° 878-2015-MTC/03 | K35: 46020
A36: =A35+1 -> 21 | C36: Santa Eulalia | D36: Lima | E36: FM | F36: 90.9 | G36: 50 | H36: AL AIRE | I36: Asociación Cultural Bethel | K36: 46035
A37: 79 | C37: Cayna | D37: Huanuco | E37: FM | F37: 92.7 | G37: 50 | H37: AL AIRE | I37: Asociación Cultural Bethel | K37: 46037
A38: =A37+1 -> 80 | C38: Ilo | D38: Moquegua | E38: FM | F38: 100.5 | G38: 500 | H38: AL AIRE | I38: Asociación Cultural Bethel | K38: 46037
A39: 99 | C39: Chimbote | D39: Ancash | E39: UHF | F39: 23 | G39: 500 | H39: FUERA AL AIRE | I39: Asociación Cultural Bethel | K39: 46040
A40: 112 | C40: Cieneguilla | D40: Lima | E40: FM | F40: 98.7 | G40: 250 | H40: AL AIRE | I40: Asociación Cultural Bethel | K40: 46050
...

Sheet ESTACIONES
A1: nº | B1: LOCALIDAD | C1: DPTO. | D1: BANDA | E1: FREC. | F1: PRESB. | G1: F.A | H1: INCIDENCIAS | I1: MOTIVO | J1: OBSERVACION | K1: ID | L1: RESPONSABLE | M1: NIVEL | N1: PRESUP S/. | O1: PRESUP $ | P1: LAT | Q1: LNG | R1: GMS | S1: ID
A2: 1 | B2: {=INDEX('informe de Gestión 2021-2025'!C:C, MATCH(S2,#REF!, 0), )} -> #REF! | C2: {=INDEX('informe de Gestión 2021-2025'!D:D, MATCH(S2,#REF!, 0), )} -> #REF! | D2: {=INDEX('informe de Gestión 2021-2025'!I:I, MATCH(S2,#REF!, 0), )} -> #REF! | E2: {=INDEX('informe de Gestión 2021-2025'!K:K, MATCH(S2,#REF!, 0), )} -> #REF! | F2: =INDEX(#REF!, MATCH(S2,#REF!, 0), ) -> #REF! | G2: {=INDEX('informe de Gestión 2021-2025'!#REF!, MATCH(S2,#REF!, 0), )} -> #REF! | H2: =INDEX(#REF!, MATCH(S2,#REF!, 0), ) -> #REF! | I2: =INDEX(#REF!, MATCH(S2,#REF!, 0), ) -> #REF! | J2: =INDEX(#REF!, MATCH(S2,#REF!, 0), ) -> #REF! | K2: =INDEX(#REF!, MATCH(S2,#REF!, 0), ) -> #REF! | L2: =INDEX(#REF!, MATCH(S2,#REF!, 0), ) -> #REF! | M2: =INDEX(#REF!, MATCH(S2,#REF!, 0), ) -> #REF! | N2: =INDEX(#REF!, MATCH(S2,#REF!, 0), ) -> #REF! | O2: =INDEX(#REF!, MATCH(S2,#REF!, 0), ) -> #REF! | P2: -9.7811639 | Q2: -77.619747 | R2: 77.61974722222222°W 9.781163888888889°S | S2: R - 1
A3: 2 | B3: {=INDEX('informe de Gestión 2021-2025'!C:C, MATCH(S3,#REF!, 0), )} -> #REF! | C3: {=INDEX('informe de Gestión 2021-2025'!D:D, MATCH(S3,#REF!, 0), )} -> #REF! | D3: {=INDEX('informe de Gestión 2021-2025'!I:I, MATCH(S3,#REF!, 0), )} -> #REF! | E3: {=INDEX('informe de Gestión 2021-2025'!K:K, MATCH(S3,#REF!, 0), )} -> #REF! | F3: =INDEX(#REF!, MATCH(S3,#REF!, 0), ) -> #REF! | G3: {=INDEX('informe de Gestión 2021-2025'!#REF!, MATCH(S3,#REF!, 0), )} -> #REF! | H3: =INDEX(#REF!, MATCH(S3,#REF!, 0), ) -> #REF! | I3: =INDEX(#REF!, MATCH(S3,#REF!, 0), ) -> #REF! | J3: =INDEX(#REF!, MATCH(S3,#REF!, 0), ) -> #REF! | K3: =INDEX(#REF!, MATCH(S3,#REF!, 0), ) -> #REF! | L3: =INDEX(#REF!, MATCH(S3,#REF!, 0), ) -> #REF! | M3: =INDEX(#REF!, MATCH(S3,#REF!, 0), ) -> #REF! | N3: =INDEX(#REF!, MATCH(S3,#REF!, 0), ) -> #REF! | O3: =INDEX(#REF!, MATCH(S3,#REF!, 0), ) -> #REF! | P3: -9.7811639 | Q3: -77.619747 | R3: 77.61974722222222°W 9.781163888888889°S | S3: R - 2
A4: 3 | B4: {=INDEX('informe de Gestión 2021-2025'!C:C, MATCH(S4,#REF!, 0), )} -> #REF! | C4: {=INDEX('informe de Gestión 2021-2025'!D:D, MATCH(S4,#REF!, 0), )} -> #REF! | D4: {=INDEX('informe de Gestión 2021-2025'!I:I, MATCH(S4,#REF!, 0), )} -> #REF! | E4: {=INDEX('informe de Gestión 2021-2025'!K:K, MATCH(S4,#REF!, 0), )} -> #REF! | F4: =INDEX(#REF!, MATCH(S4,#REF!, 0), ) -> #REF! | G4: {=INDEX('informe de Gestión 2021-2025'!#REF!, MATCH(S4,#REF!, 0), )} -> #REF! | H4: =INDEX(#REF!, MATCH(S4,#REF!, 0), ) -> #REF! | I4: =INDEX(#REF!, MATCH(S4,#REF!, 0), ) -> #REF! | J4: =INDEX(#REF!, MATCH(S4,#REF!, 0), ) -> #REF! | K4: =INDEX(#REF!, MATCH(S4,#REF!, 0), ) -> #REF! | L4: =INDEX(#REF!, MATCH(S4,#REF!, 0), ) -> #REF! | M4: =INDEX(#REF!, MATCH(S4,#REF!, 0), ) -> #REF! | N4: =INDEX(#REF!, MATCH(S4,#REF!, 0), ) -> #REF! | O4: =INDEX(#REF!, MATCH(S4,#REF!, 0), ) -> #REF! | P4: -4.90725 | Q4: -81.053669 | R4: 81.05366944444444°W 4.90725°S | S4: R - 3
A5: 4 | B5: {=INDEX('informe de Gestión 2021-2025'!C:C, MATCH(S5,#REF!, 0), )} -> #REF! | C5: {=INDEX('informe de Gestión 2021-2025'!D:D, MATCH(S5,#REF!, 0), )} -> #REF! | D5: {=INDEX('informe de Gestión 2021-2025'!I:I, MATCH(S5,#REF!, 0), )} -> #REF! | E5: {=INDEX('informe de Gestión 2021-2025'!K:K, MATCH(S5,#REF!, 0), )} -> #REF! | F5: =INDEX(#REF!, MATCH(S5,#REF!, 0), ) -> #REF! | G5: {=INDEX('informe de Gestión 2021-2025'!#REF!, MATCH(S5,#REF!, 0), )} -> #REF! | H5: =INDEX(#REF!, MATCH(S5,#REF!, 0), ) -> #REF! | I5: =INDEX(#REF!, MATCH(S5,#REF!, 0), ) -> #REF! | J5: =INDEX(#REF!, MATCH(S5,#REF!, 0), ) -> #REF! | K5: =INDEX(#REF!, MATCH(S5,#REF!, 0), ) -> #REF! | L5: =INDEX(#REF!, MATCH(S5,#REF!, 0), ) -> #REF! | M5: =INDEX(#REF!, MATCH(S5,#REF!, 0), ) -> #REF! | N5: =INDEX(#REF!, MATCH(S5,#REF!, 0), ) -> #REF! | O5: =INDEX(#REF!, MATCH(S5,#REF!, 0), ) -> #REF! | P5: -4.6357222 | Q5: -79.717861 | R5: 79.71786111111112°W 4.635722222222221°S | S5: R - 4
A6: 5 | B6: {=INDEX('informe de Gestión 2021-2025'!C:C, MATCH(S6,#REF!, 0), )} -> #REF! | C6: {=INDEX('informe de Gestión 2021-2025'!D:D, MATCH(S6,#REF!, 0), )} -> #REF! | D6: {=INDEX('informe de Gestión 2021-2025'!I:I, MATCH(S6,#REF!, 0), )} -> #REF! | E6: {=INDEX('informe de Gestión 2021-2025'!K:K, MATCH(S6,#REF!, 0), )} -> #REF! | F6: =INDEX(#REF!, MATCH(S6,#REF!, 0), ) -> #REF! | G6: {=INDEX('informe de Gestión 2021-2025'!#REF!, MATCH(S6,#REF!, 0), )} -> #REF! | H6: =INDEX(#REF!, MATCH(S6,#REF!, 0), ) -> #REF! | I6: =INDEX(#REF!, MATCH(S6,#REF!, 0), ) -> #REF! | J6: =INDEX(#REF!, MATCH(S6,#REF!, 0), ) -> #REF! | K6: =INDEX(#REF!, MATCH(S6,#REF!, 0), ) -> #REF! | L6: =INDEX(#REF!, MATCH(S6,#REF!, 0), ) -> #REF! | M6: =INDEX(#REF!, MATCH(S6,#REF!, 0), ) -> #REF! | N6: =INDEX(#REF!, MATCH(S6,#REF!, 0), ) -> #REF! | O6: =INDEX(#REF!, MATCH(S6,#REF!, 0), ) -> #REF! | P6: -4.6357222 | Q6: -79.717861 | R6: 79.71786111111112°W 4.635722222222221°S | S6: R - 5
A7: 6 | B7: {=INDEX('informe de Gestión 2021-2025'!C:C, MATCH(S7,#REF!, 0), )} -> #REF! | C7: {=INDEX('informe de Gestión 2021-2025'!D:D, MATCH(S7,#REF!, 0), )} -> #REF! | D7: {=INDEX('informe de Gestión 2021-2025'!I:I, MATCH(S7,#REF!, 0), )} -> #REF! | E7: {=INDEX('informe de Gestión 2021-2025'!K:K, MATCH(S7,#REF!, 0), )} -> #REF! | F7: =INDEX(#REF!, MATCH(S7,#REF!, 0), ) -> #REF! | G7: {=INDEX('informe de Gestión 2021-2025'!#REF!, MATCH(S7,#REF!, 0), )} -> #REF! | H7: =INDEX(#REF!, MATCH(S7,#REF!, 0), ) -> #REF! | I7: =INDEX(#REF!, MATCH(S7,#REF!, 0), ) -> #REF! | J7: =INDEX(#REF!, MATCH(S7,#REF!, 0), ) -> #REF! | K7: =INDEX(#REF!, MATCH(S7,#REF!, 0), ) -> #REF! | L7: =INDEX(#REF!, MATCH(S7,#REF!, 0), ) -> #REF! | M7: =INDEX(#REF!, MATCH(S7,#REF!, 0), ) -> #REF! | N7: =INDEX(#REF!, MATCH(S7,#REF!, 0), ) -> #REF! | O7: =INDEX(#REF!, MATCH(S7,#REF!, 0), ) -> #REF! | P7: -5.6363889 | Q7: -78.508056 | R7: 78.50805555555556°W 5.636388888888888°S | S7: R - 6
A8: 7 | B8: {=INDEX('informe de Gestión 2021-2025'!C:C, MATCH(S8,#REF!, 0), )} -> #REF! | C8: {=INDEX('informe de Gestión 2021-2025'!D:D, MATCH(S8,#REF!, 0), )} -> #REF! | D8: {=INDEX('informe de Gestión 2021-2025'!I:I, MATCH(S8,#REF!, 0), )} -> #REF! | E8: {=INDEX('informe de Gestión 2021-2025'!K:K, MATCH(S8,#REF!, 0), )} -> #REF! | F8: =INDEX(#REF!, MATCH(S8,#REF!, 0), ) -> #REF! | G8: {=INDEX('informe de Gestión 2021-2025'!#REF!, MATCH(S8,#REF!, 0), )} -> #REF! | H8: =INDEX(#REF!, MATCH(S8,#REF!, 0), ) -> #REF! | I8: =INDEX(#REF!, MATCH(S8,#REF!, 0), ) -> #REF! | J8: =INDEX(#REF!, MATCH(S8,#REF!, 0), ) -> #REF! | K8: =INDEX(#REF!, MATCH(S8,#REF!, 0), ) -> #REF! | L8: =INDEX(#REF!, MATCH(S8,#REF!, 0), ) -> #REF! | M8: =INDEX(#REF!, MATCH(S8,#REF!, 0), ) -> #REF! | N8: =INDEX(#REF!, MATCH(S8,#REF!, 0), ) -> #REF! | O8: =INDEX(#REF!, MATCH(S8,#REF!, 0), ) -> #REF! | P8: -5.6359722 | Q8: -78.508667 | R8: 78.50866666666667°W 5.635972222222222°S | S8: R - 7
A9: 8 | B9: {=INDEX('informe de Gestión 2021-2025'!C:C, MATCH(S9,#REF!, 0), )} -> #REF! | C9: {=INDEX('informe de Gestión 2021-2025'!D:D, MATCH(S9,#REF!, 0), )} -> #REF! | D9: {=INDEX('informe de Gestión 2021-2025'!I:I, MATCH(S9,#REF!, 0), )} -> #REF! | E9: {=INDEX('informe de Gestión 2021-2025'!K:K, MATCH(S9,#REF!, 0), )} -> #REF! | F9: =INDEX(#REF!, MATCH(S9,#REF!, 0), ) -> #REF! | G9: {=INDEX('informe de Gestión 2021-2025'!#REF!, MATCH(S9,#REF!, 0), )} -> #REF! | H9: =INDEX(#REF!, MATCH(S9,#REF!, 0), ) -> #REF! | I9: =INDEX(#REF!, MATCH(S9,#REF!, 0), ) -> #REF! | J9: =INDEX(#REF!, MATCH(S9,#REF!, 0), ) -> #REF! | K9: =INDEX(#REF!, MATCH(S9,#REF!, 0), ) -> #REF! | L9: =INDEX(#REF!, MATCH(S9,#REF!, 0), ) -> #REF! | M9: =INDEX(#REF!, MATCH(S9,#REF!, 0), ) -> #REF! | N9: =INDEX(#REF!, MATCH(S9,#REF!, 0), ) -> #REF! | O9: =INDEX(#REF!, MATCH(S9,#REF!, 0), ) -> #REF! | P9: -5.7631389 | Q9: -78.439 | R9: 78.43900000000001°W 5.763138888888889°S | S9: R - 8
A10: 9 | B10: {=INDEX('informe de Gestión 2021-2025'!C:C, MATCH(S10,#REF!, 0), )} -> #REF! | C10: {=INDEX('informe de Gestión 2021-2025'!D:D, MATCH(S10,#REF!, 0), )} -> #REF! | D10: {=INDEX('informe de Gestión 2021-2025'!I:I, MATCH(S10,#REF!, 0), )} -> #REF! | E10: {=INDEX('informe de Gestión 2021-2025'!K:K, MATCH(S10,#REF!, 0), )} -> #REF! | F10: =INDEX(#REF!, MATCH(S10,#REF!, 0), ) -> #REF! | G10: {=INDEX('informe de Gestión 2021-2025'!#REF!, MATCH(S10,#REF!, 0), )} -> #REF! | H10: =INDEX(#REF!, MATCH(S10,#REF!, 0), ) -> #REF! | I10: =INDEX(#REF!, MATCH(S10,#REF!, 0), ) -> #REF! | J10: =INDEX(#REF!, MATCH(S10,#REF!, 0), ) -> #REF! | K10: =INDEX(#REF!, MATCH(S10,#REF!, 0), ) -> #REF! | L10: =INDEX(#REF!, MATCH(S10,#REF!, 0), ) -> #REF! | M10: =INDEX(#REF!, MATCH(S10,#REF!, 0), ) -> #REF! | N10: =INDEX(#REF!, MATCH(S10,#REF!, 0), ) -> #REF! | O10: =INDEX(#REF!, MATCH(S10,#REF!, 0), ) -> #REF! | P10: -6.6993667 | Q10: -78.508639 | R10: 78.50863888888888°W 6.699366666666667°S | S10: R - 9
A11: 10 | B11: {=INDEX('informe de Gestión 2021-2025'!C:C, MATCH(S11,#REF!, 0), )} -> #REF! | C11: {=INDEX('informe de Gestión 2021-2025'!D:D, MATCH(S11,#REF!, 0), )} -> #REF! | D11: {=INDEX('informe de Gestión 2021-2025'!I:I, MATCH(S11,#REF!, 0), )} -> #REF! | E11: {=INDEX('informe de Gestión 2021-2025'!K:K, MATCH(S11,#REF!, 0), )} -> #REF! | F11: =INDEX(#REF!, MATCH(S11,#REF!, 0), ) -> #REF! | G11: {=INDEX('informe de Gestión 2021-2025'!#REF!, MATCH(S11,#REF!, 0), )} -> #REF! | H11: =INDEX(#REF!, MATCH(S11,#REF!, 0), ) -> #REF! | I11: =INDEX(#REF!, MATCH(S11,#REF!, 0), ) -> #REF! | J11: =INDEX(#REF!, MATCH(S11,#REF!, 0), ) -> #REF! | K11: =INDEX(#REF!, MATCH(S11,#REF!, 0), ) -> #REF! | L11: =INDEX(#REF!, MATCH(S11,#REF!, 0), ) -> #REF! | M11: =INDEX(#REF!, MATCH(S11,#REF!, 0), ) -> #REF! | N11: =INDEX(#REF!, MATCH(S11,#REF!, 0), ) -> #REF! | O11: =INDEX(#REF!, MATCH(S11,#REF!, 0), ) -> #REF! | P11: -8.39325 | Q11: -78.007194 | R11: 78.00719444444445°W 8.39325°S | S11: R - 10
A12: 11 | B12: {=INDEX('informe de Gestión 2021-2025'!C:C, MATCH(S12,#REF!, 0), )} -> #REF! | C12: {=INDEX('informe de Gestión 2021-2025'!D:D, MATCH(S12,#REF!, 0), )} -> #REF! | D12: {=INDEX('informe de Gestión 2021-2025'!I:I, MATCH(S12,#REF!, 0), )} -> #REF! | E12: {=INDEX('informe de Gestión 2021-2025'!K:K, MATCH(S12,#REF!, 0), )} -> #REF! | F12: =INDEX(#REF!, MATCH(S12,#REF!, 0), ) -> #REF! | G12: {=INDEX('informe de Gestión 2021-2025'!#REF!, MATCH(S12,#REF!, 0), )} -> #REF! | H12: =INDEX(#REF!, MATCH(S12,#REF!, 0), ) -> #REF! | I12: =INDEX(#REF!, MATCH(S12,#REF!, 0), ) -> #REF! | J12: =INDEX(#REF!, MATCH(S12,#REF!, 0), ) -> #REF! | K12: =INDEX(#REF!, MATCH(S12,#REF!, 0), ) -> #REF! | L12: =INDEX(#REF!, MATCH(S12,#REF!, 0), ) -> #REF! | M12: =INDEX(#REF!, MATCH(S12,#REF!, 0), ) -> #REF! | N12: =INDEX(#REF!, MATCH(S12,#REF!, 0), ) -> #REF! | O12: =INDEX(#REF!, MATCH(S12,#REF!, 0), ) -> #REF! | P12: -8.39325 | Q12: -78.007194 | R12: 78.00719444444445°W 8.39325°S | S12: R - 11
A13: 12 | B13: {=INDEX('informe de Gestión 2021-2025'!C:C, MATCH(S13,#REF!, 0), )} -> #REF! | C13: {=INDEX('informe de Gestión 2021-2025'!D:D, MATCH(S13,#REF!, 0), )} -> #REF! | D13: {=INDEX('informe de Gestión 2021-2025'!I:I, MATCH(S13,#REF!, 0), )} -> #REF! | E13: {=INDEX('informe de Gestión 2021-2025'!K:K, MATCH(S13,#REF!, 0), )} -> #REF! | F13: =INDEX(#REF!, MATCH(S13,#REF!, 0), ) -> #REF! | G13: {=INDEX('informe de Gestión 2021-2025'!#REF!, MATCH(S13,#REF!, 0), )} -> #REF! | H13: =INDEX(#REF!, MATCH(S13,#REF!, 0), ) -> #REF! | I13: =INDEX(#REF!, MATCH(S13,#REF!, 0), ) -> #REF! | J13: =INDEX(#REF!, MATCH(S13,#REF!, 0), ) -> #REF! | K13: =INDEX(#REF!, MATCH(S13,#REF!, 0), ) -> #REF! | L13: =INDEX(#REF!, MATCH(S13,#REF!, 0), ) -> #REF! | M13: =INDEX(#REF!, MATCH(S13,#REF!, 0), ) -> #REF! | N13: =INDEX(#REF!, MATCH(S13,#REF!, 0), ) -> #REF! | O13: =INDEX(#REF!, MATCH(S13,#REF!, 0), ) -> #REF! | P13: -7.6234722 | Q13: -78.039417 | R13: 78.03941666666667°W 7.623472222222222°S | S13: R - 12
... A39: 38 | B39: {=INDEX('informe de Gestión 2021-2025'!C:C, MATCH(S39,#REF!, 0), )} -> #REF! | C39: {=INDEX('informe de Gestión 2021-2025'!D:D, MATCH(S39,#REF!, 0), )} -> #REF! | D39: {=INDEX('informe de Gestión 2021-2025'!I:I, MATCH(S39,#REF!, 0), )} -> #REF! | E39: {=INDEX('informe de Gestión 2021-2025'!K:K, MATCH(S39,#REF!, 0), )} -> #REF! | F39: =INDEX(#REF!, MATCH(S39,#REF!, 0), ) -> #REF! | G39: {=INDEX('informe de Gestión 2021-2025'!#REF!, MATCH(S39,#REF!, 0), )} -> #REF! | H39: =INDEX(#REF!, MATCH(S39,#REF!, 0), ) -> #REF! | I39: =INDEX(#REF!, MATCH(S39,#REF!, 0), ) -> #REF! | J39: =INDEX(#REF!, MATCH(S39,#REF!, 0), ) -> #REF! | K39: =INDEX(#REF!, MATCH(S39,#REF!, 0), ) -> #REF! | L39: =INDEX(#REF!, MATCH(S39,#REF!, 0), ) -> #REF! | M39: =INDEX(#REF!, MATCH(S39,#REF!, 0), ) -> #REF! | N39: =INDEX(#REF!, MATCH(S39,#REF!, 0), ) -> #REF! | O39: =INDEX(#REF!, MATCH(S39,#REF!, 0), ) -> #REF! | P39: -8.2655111 | Q39: -77.850892 | R39: 77.85089166666666°W 8.265511111111111°S | S39: R - 38
A40: 39 | B40: {=INDEX('informe de Gestión 2021-2025'!C:C, MATCH(S40,#REF!, 0), )} -> #REF! | C40: {=INDEX('informe de Gestión 2021-2025'!D:D, MATCH(S40,#REF!, 0), )} -> #REF! | D40: {=INDEX('informe de Gestión 2021-2025'!I:I, MATCH(S40,#REF!, 0), )} -> #REF! | E40: {=INDEX('informe de Gestión 2021-2025'!K:K, MATCH(S40,#REF!, 0), )} -> #REF! | F40: =INDEX(#REF!, MATCH(S40,#REF!, 0), ) -> #REF! | G40: {=INDEX('informe de Gestión 2021-2025'!#REF!, MATCH(S40,#REF!, 0), )} -> #REF! | H40: =INDEX(#REF!, MATCH(S40,#REF!, 0), ) -> #REF! | I40: =INDEX(#REF!, MATCH(S40,#REF!, 0), ) -> #REF! | J40: =INDEX(#REF!, MATCH(S40,#REF!, 0), ) -> #REF! | K40: =INDEX(#REF!, MATCH(S40,#REF!, 0), ) -> #REF! | L40: =INDEX(#REF!, MATCH(S40,#REF!, 0), ) -> #REF! | M40: =INDEX(#REF!, MATCH(S40,#REF!, 0), ) -> #REF! | N40: =INDEX(#REF!, MATCH(S40,#REF!, 0), ) -> #REF! | O40: =INDEX(#REF!, MATCH(S40,#REF!, 0), ) -> #REF! | S40: R - 39
A41: 40 | B41: {=INDEX('informe de Gestión 2021-2025'!C:C, MATCH(S41,#REF!, 0), )} -> #REF! | C41: {=INDEX('informe de Gestión 2021-2025'!D:D, MATCH(S41,#REF!, 0), )} -> #REF! | D41: {=INDEX('informe de Gestión 2021-2025'!I:I, MATCH(S41,#REF!, 0), )} -> #REF! | E41: {=INDEX('informe de Gestión 2021-2025'!K:K, MATCH(S41,#REF!, 0), )} -> #REF! | F41: =INDEX(#REF!, MATCH(S41,#REF!, 0), ) -> #REF! | G41: {=INDEX('informe de Gestión 2021-2025'!#REF!, MATCH(S41,#REF!, 0), )} -> #REF! | H41: =INDEX(#REF!, MATCH(S41,#REF!, 0), ) -> #REF! | I41: =INDEX(#REF!, MATCH(S41,#REF!, 0), ) -> #REF! | J41: =INDEX(#REF!, MATCH(S41,#REF!, 0), ) -> #REF! | K41: =INDEX(#REF!, MATCH(S41,#REF!, 0), ) -> #REF! | L41: =INDEX(#REF!, MATCH(S41,#REF!, 0), ) -> #REF! | M41: =INDEX(#REF!, MATCH(S41,#REF!, 0), ) -> #REF! | N41: =INDEX(#REF!, MATCH(S41,#REF!, 0), ) -> #REF! | O41: =INDEX(#REF!, MATCH(S41,#REF!, 0), ) -> #REF! | P41: -5.9279444 | Q41: -77.941417 | R41: 77.94141666666667°W 5.927944444444445°S | S41: R - 40
A42: 41 | B42: {=INDEX('informe de Gestión 2021-2025'!C:C, MATCH(S42,#REF!, 0), )} -> #REF! | C42: {=INDEX('informe de Gestión 2021-2025'!D:D, MATCH(S42,#REF!, 0), )} -> #REF! | D42: {=INDEX('informe de Gestión 2021-2025'!I:I, MATCH(S42,#REF!, 0), )} -> #REF! | E42: {=INDEX('informe de Gestión 2021-2025'!K:K, MATCH(S42,#REF!, 0), )} -> #REF! | F42: =INDEX(#REF!, MATCH(S42,#REF!, 0), ) -> #REF! | G42: {=INDEX('informe de Gestión 2021-2025'!#REF!, MATCH(S42,#REF!, 0), )} -> #REF! | H42: =INDEX(#REF!, MATCH(S42,#REF!, 0), ) -> #REF! | I42: =INDEX(#REF!, MATCH(S42,#REF!, 0), ) -> #REF! | J42: =INDEX(#REF!, MATCH(S42,#REF!, 0), ) -> #REF! | K42: =INDEX(#REF!, MATCH(S42,#REF!, 0), ) -> #REF! | L42: =INDEX(#REF!, MATCH(S42,#REF!, 0), ) -> #REF! | M42: =INDEX(#REF!, MATCH(S42,#REF!, 0), ) -> #REF! | N42: =INDEX(#REF!, MATCH(S42,#REF!, 0), ) -> #REF! | O42: =INDEX(#REF!, MATCH(S42,#REF!, 0), ) -> #REF! | P42: -6.3729722 | Q42: -78.802472 | R42: 78.80247222222222°W 6.372972222222222°S | S42: R - 41
A43: 42 | B43: {=INDEX('informe de Gestión 2021-2025'!C:C, MATCH(S43,#REF!, 0), )} -> #REF! | C43: {=INDEX('informe de Gestión 2021-2025'!D:D, MATCH(S43,#REF!, 0), )} -> #REF! | D43: {=INDEX('informe de Gestión 2021-2025'!I:I, MATCH(S43,#REF!, 0), )} -> #REF! | E43: {=INDEX('informe de Gestión 2021-2025'!K:K, MATCH(S43,#REF!, 0), )} -> #REF! | F43: =INDEX(#REF!, MATCH(S43,#REF!, 0), ) -> #REF! | G43: {=INDEX('informe de Gestión 2021-2025'!#REF!, MATCH(S43,#REF!, 0), )} -> #REF! | H43: =INDEX(#REF!, MATCH(S43,#REF!, 0), ) -> #REF! | I43: =INDEX(#REF!, MATCH(S43,#REF!, 0), ) -> #REF! | J43: =INDEX(#REF!, MATCH(S43,#REF!, 0), ) -> #REF! | K43: =INDEX(#REF!, MATCH(S43,#REF!, 0), ) -> #REF! | L43: =INDEX(#REF!, MATCH(S43,#REF!, 0), ) -> #REF! | M43: =INDEX(#REF!, MATCH(S43,#REF!, 0), ) -> #REF! | N43: =INDEX(#REF!, MATCH(S43,#REF!, 0), ) -> #REF! | O43: =INDEX(#REF!, MATCH(S43,#REF!, 0), ) -> #REF! | P43: -8.6013056 | Q43: -77.139889 | R43: 77.13988888888889°W 8.601305555555555°S | S43: R - 42
A44: 43 | B44: {=INDEX('informe de Gestión 2021-2025'!C:C, MATCH(S44,#REF!, 0), )} -> #REF! | C44: {=INDEX('informe de Gestión 2021-2025'!D:D, MATCH(S44,#REF!, 0), )} -> #REF! | D44: {=INDEX('informe de Gestión 2021-2025'!I:I, MATCH(S44,#REF!, 0), )} -> #REF! | E44: {=INDEX('informe de Gestión 2021-2025'!K:K, MATCH(S44,#REF!, 0), )} -> #REF! | F44: =INDEX(#REF!, MATCH(S44,#REF!, 0), ) -> #REF! | G44: {=INDEX('informe de Gestión 2021-2025'!#REF!, MATCH(S44,#REF!, 0), )} -> #REF! | H44: =INDEX(#REF!, MATCH(S44,#REF!, 0), ) -> #REF! | I44: =INDEX(#REF!, MATCH(S44,#REF!, 0), ) -> #REF! | J44: =INDEX(#REF!, MATCH(S44,#REF!, 0), ) -> #REF! | K44: =INDEX(#REF!, MATCH(S44,#REF!, 0), ) -> #REF! | L44: =INDEX(#REF!, MATCH(S44,#REF!, 0), ) -> #REF! | M44: =INDEX(#REF!, MATCH(S44,#REF!, 0), ) -> #REF! | N44: =INDEX(#REF!, MATCH(S44,#REF!, 0), ) -> #REF! | O44: =INDEX(#REF!, MATCH(S44,#REF!, 0), ) -> #REF! | P44: -7.8130556 | Q44: -78.049111 | R44: 78.0491111111111°W 7.813055555555556°S | S44: R - 43
A45: 44 | B45: {=INDEX('informe de Gestión 2021-2025'!C:C, MATCH(S45,#REF!, 0), )} -> #REF! | C45: {=INDEX('informe de Gestión 2021-2025'!D:D, MATCH(S45,#REF!, 0), )} -> #REF! | D45: {=INDEX('informe de Gestión 2021-2025'!I:I, MATCH(S45,#REF!, 0), )} -> #REF! | E45: {=INDEX('informe de Gestión 2021-2025'!K:K, MATCH(S45,#REF!, 0), )} -> #REF! | F45: =INDEX(#REF!, MATCH(S45,#REF!, 0), ) -> #REF! | G45: {=INDEX('informe de Gestión 2021-2025'!#REF!, MATCH(S45,#REF!, 0), )} -> #REF! | H45: =INDEX(#REF!, MATCH(S45,#REF!, 0), ) -> #REF! | I45: =INDEX(#REF!, MATCH(S45,#REF!, 0), ) -> #REF! | J45: =INDEX(#REF!, MATCH(S45,#REF!, 0), ) -> #REF! | K45: =INDEX(#REF!, MATCH(S45,#REF!, 0), ) -> #REF! | L45: =INDEX(#REF!, MATCH(S45,#REF!, 0), ) -> #REF! | M45: =INDEX(#REF!, MATCH(S45,#REF!, 0), ) -> #REF! | N45: =INDEX(#REF!, MATCH(S45,#REF!, 0), ) -> #REF! | O45: =INDEX(#REF!, MATCH(S45,#REF!, 0), ) -> #REF! | P45: -5.2429056 | Q45: -79.433769 | R45: 79.43376944444445°W 5.242905555555556°S | S45: R - 44
A46: 45 | B46: {=INDEX('informe de Gestión 2021-2025'!C:C, MATCH(S46,#REF!, 0), )} -> #REF! | C46: {=INDEX('informe de Gestión 2021-2025'!D:D, MATCH(S46,#REF!, 0), )} -> #REF! | D46: {=INDEX('informe de Gestión 2021-2025'!I:I, MATCH(S46,#REF!, 0), )} -> #REF! | E46: {=INDEX('informe de Gestión 2021-2025'!K:K, MATCH(S46,#REF!, 0), )} -> #REF! | F46: =INDEX(#REF!, MATCH(S46,#REF!, 0), ) -> #REF! | G46: {=INDEX('informe de Gestión 2021-2025'!#REF!, MATCH(S46,#REF!, 0), )} -> #REF! | H46: =INDEX(#REF!, MATCH(S46,#REF!, 0), ) -> #REF! | I46: =INDEX(#REF!, MATCH(S46,#REF!, 0), ) -> #REF! | J46: =INDEX(#REF!, MATCH(S46,#REF!, 0), ) -> #REF! | K46: =INDEX(#REF!, MATCH(S46,#REF!, 0), ) -> #REF! | L46: =INDEX(#REF!, MATCH(S46,#REF!, 0), ) -> #REF! | M46: =INDEX(#REF!, MATCH(S46,#REF!, 0), ) -> #REF! | N46: =INDEX(#REF!, MATCH(S46,#REF!, 0), ) -> #REF! | O46: =INDEX(#REF!, MATCH(S46,#REF!, 0), ) -> #REF! | P46: -5.2429056 | Q46: -79.433769 | R46: 79.43376944444445°W 5.242905555555556°S | S46: R - 45
A47: 46 | B47: {=INDEX('informe de Gestión 2021-2025'!C:C, MATCH(S47,#REF!, 0), )} -> #REF! | C47: {=INDEX('informe de Gestión 2021-2025'!D:D, MATCH(S47,#REF!, 0), )} -> #REF! | D47: {=INDEX('informe de Gestión 2021-2025'!I:I, MATCH(S47,#REF!, 0), )} -> #REF! | E47: {=INDEX('informe de Gestión 2021-2025'!K:K, MATCH(S47,#REF!, 0), )} -> #REF! | F47: =INDEX(#REF!, MATCH(S47,#REF!, 0), ) -> #REF! | G47: {=INDEX('informe de Gestión 2021-2025'!#REF!, MATCH(S47,#REF!, 0), )} -> #REF! | H47: =INDEX(#REF!, MATCH(S47,#REF!, 0), ) -> #REF! | I47: =INDEX(#REF!, MATCH(S47,#REF!, 0), ) -> #REF! | J47: =INDEX(#REF!, MATCH(S47,#REF!, 0), ) -> #REF! | K47: =INDEX(#REF!, MATCH(S47,#REF!, 0), ) -> #REF! | L47: =INDEX(#REF!, MATCH(S47,#REF!, 0), ) -> #REF! | M47: =INDEX(#REF!, MATCH(S47,#REF!, 0), ) -> #REF! | N47: =INDEX(#REF!, MATCH(S47,#REF!, 0), ) -> #REF! | O47: =INDEX(#REF!, MATCH(S47,#REF!, 0), ) -> #REF! | P47: -9.7226389 | Q47: -77.816194 | R47: 77.81619444444445°W 9.72263888888889°S | S47: R - 46
A48: 47 | B48: {=INDEX('informe de Gestión 2021-2025'!C:C, MATCH(S48,#REF!, 0), )} -> #REF! | C48: {=INDEX('informe de Gestión 2021-2025'!D:D, MATCH(S48,#REF!, 0), )} -> #REF! | D48: {=INDEX('informe de Gestión 2021-2025'!I:I, MATCH(S48,#REF!, 0), )} -> #REF! | E48: {=INDEX('informe de Gestión 2021-2025'!K:K, MATCH(S48,#REF!, 0), )} -> #REF! | F48: =INDEX(#REF!, MATCH(S48,#REF!, 0), ) -> #REF! | G48: {=INDEX('informe de Gestión 2021-2025'!#REF!, MATCH(S48,#REF!, 0), )} -> #REF! | H48: =INDEX(#REF!, MATCH(S48,#REF!, 0), ) -> #REF! | I48: =INDEX(#REF!, MATCH(S48,#REF!, 0), ) -> #REF! | J48: =INDEX(#REF!, MATCH(S48,#REF!, 0), ) -> #REF! | K48: =INDEX(#REF!, MATCH(S48,#REF!, 0), ) -> #REF! | L48: =INDEX(#REF!, MATCH(S48,#REF!, 0), ) -> #REF! | M48: =INDEX(#REF!, MATCH(S48,#REF!, 0), ) -> #REF! | N48: =INDEX(#REF!, MATCH(S48,#REF!, 0), ) -> #REF! | O48: =INDEX(#REF!, MATCH(S48,#REF!, 0), ) -> #REF! | P48: -9.5198611 | Q48: -77.516611 | R48: 77.51661111111112°W 9.519861111111112°S | S48: R - 47
A49: 48 | B49: {=INDEX('informe de Gestión 2021-2025'!C:C, MATCH(S49,#REF!, 0), )} -> #REF! | C49: {=INDEX('informe de Gestión 2021-2025'!D:D, MATCH(S49,#REF!, 0), )} -> #REF! | D49: {=INDEX('informe de Gestión 2021-2025'!I:I, MATCH(S49,#REF!, 0), )} -> #REF! | E49: {=INDEX('informe de Gestión 2021-2025'!K:K, MATCH(S49,#REF!, 0), )} -> #REF! | F49: =INDEX(#REF!, MATCH(S49,#REF!, 0), ) -> #REF! | G49: {=INDEX('informe de Gestión 2021-2025'!#REF!, MATCH(S49,#REF!, 0), )} -> #REF! | H49: =INDEX(#REF!, MATCH(S49,#REF!, 0), ) -> #REF! | I49: =INDEX(#REF!, MATCH(S49,#REF!, 0), ) -> #REF! | J49: =INDEX(#REF!, MATCH(S49,#REF!, 0), ) -> #REF! | K49: =INDEX(#REF!, MATCH(S49,#REF!, 0), ) -> #REF! | L49: =INDEX(#REF!, MATCH(S49,#REF!, 0), ) -> #REF! | M49: =INDEX(#REF!, MATCH(S49,#REF!, 0), ) -> #REF! | N49: =INDEX(#REF!, MATCH(S49,#REF!, 0), ) -> #REF! | O49: =INDEX(#REF!, MATCH(S49,#REF!, 0), ) -> #REF! | P49: -9.5198056 | Q49: -77.516611 | R49: 77.51661111111112°W 9.519805555555557°S | S49: R - 48
A50: 49 | B50: {=INDEX('informe de Gestión 2021-2025'!C:C, MATCH(S50,#REF!, 0), )} -> #REF! | C50: {=INDEX('informe de Gestión 2021-2025'!D:D, MATCH(S50,#REF!, 0), )} -> #REF! | D50: {=INDEX('informe de Gestión 2021-2025'!I:I, MATCH(S50,#REF!, 0), )} -> #REF! | E50: {=INDEX('informe de Gestión 2021-2025'!K:K, MATCH(S50,#REF!, 0), )} -> #REF! | F50: =INDEX(#REF!, MATCH(S50,#REF!, 0), ) -> #REF! | G50: {=INDEX('informe de Gestión 2021-2025'!#REF!, MATCH(S50,#REF!, 0), )} -> #REF! | H50: =INDEX(#REF!, MATCH(S50,#REF!, 0), ) -> #REF! | I50: =INDEX(#REF!, MATCH(S50,#REF!, 0), ) -> #REF! | J50: =INDEX(#REF!, MATCH(S50,#REF!, 0), ) -> #REF! | K50: =INDEX(#REF!, MATCH(S50,#REF!, 0), ) -> #REF! | L50: =INDEX(#REF!, MATCH(S50,#REF!, 0), ) -> #REF! | M50: =INDEX(#REF!, MATCH(S50,#REF!, 0), ) -> #REF! | N50: =INDEX(#REF!, MATCH(S50,#REF!, 0), ) -> #REF! | O50: =INDEX(#REF!, MATCH(S50,#REF!, 0), ) -> #REF! | P50: -9.3481111 | Q50: -77.17625 | R50: 77.17625000000001°W 9.348111111111113°S | S50: R - 49
A51: 50 | B51: {=INDEX('informe de Gestión 2021-2025'!C:C, MATCH(S51,#REF!, 0), )} -> #REF! | C51: {=INDEX('informe de Gestión 2021-2025'!D:D, MATCH(S51,#REF!, 0), )} -> #REF! | D51: {=INDEX('informe de Gestión 2021-2025'!I:I, MATCH(S51,#REF!, 0), )} -> #REF! | E51: {=INDEX('informe de Gestión 2021-2025'!K:K, MATCH(S51,#REF!, 0), )} -> #REF! | F51: =INDEX(#REF!, MATCH(S51,#REF!, 0), ) -> #REF! | G51: {=INDEX('informe de Gestión 2021-2025'!#REF!, MATCH(S51,#REF!, 0), )} -> #REF! | H51: =INDEX(#REF!, MATCH(S51,#REF!, 0), ) -> #REF! | I51: =INDEX(#REF!, MATCH(S51,#REF!, 0), ) -> #REF! | J51: =INDEX(#REF!, MATCH(S51,#REF!, 0), ) -> #REF! | K51: =INDEX(#REF!, MATCH(S51,#REF!, 0), ) -> #REF! | L51: =INDEX(#REF!, MATCH(S51,#REF!, 0), ) -> #REF! | M51: =INDEX(#REF!, MATCH(S51,#REF!, 0), ) -> #REF! | N51: =INDEX(#REF!, MATCH(S51,#REF!, 0), ) -> #REF! | O51: =INDEX(#REF!, MATCH(S51,#REF!, 0), ) -> #REF! | P51: -10.074139 | Q51: -78.150333 | R51: 78.15033333333334°W 10.07413888888889°S | S51: R - 50
A52: 51 | B52: {=INDEX('informe de Gestión 2021-2025'!C:C, MATCH(S52,#REF!, 0), )} -> #REF! | C52: {=INDEX('informe de Gestión 2021-2025'!D:D, MATCH(S52,#REF!, 0), )} -> #REF! | D52: {=INDEX('informe de Gestión 2021-2025'!I:I, MATCH(S52,#REF!, 0), )} -> #REF! | E52: {=INDEX('informe de Gestión 2021-2025'!K:K, MATCH(S52,#REF!, 0), )} -> #REF! | F52: =INDEX(#REF!, MATCH(S52,#REF!, 0), ) -> #REF! | G52: {=INDEX('informe de Gestión 2021-2025'!#REF!, MATCH(S52,#REF!, 0), )} -> #REF! | H52: =INDEX(#REF!, MATCH(S52,#REF!, 0), ) -> #REF! | I52: =INDEX(#REF!, MATCH(S52,#REF!, 0), ) -> #REF! | J52: =INDEX(#REF!, MATCH(S52,#REF!, 0), ) -> #REF! | K52: =INDEX(#REF!, MATCH(S52,#REF!, 0), ) -> #REF! | L52: =INDEX(#REF!, MATCH(S52,#REF!, 0), ) -> #REF! | M52: =INDEX(#REF!, MATCH(S52,#REF!, 0), ) -> #REF! | N52: =INDEX(#REF!, MATCH(S52,#REF!, 0), ) -> #REF! | O52: =INDEX(#REF!, MATCH(S52,#REF!, 0), ) -> #REF! | P52: -10.074139 | Q52: -78.150333 | R52: 78.15033333333334°W 10.07413888888889°S | S52: R - 51
... A85: 84 | B85: {=INDEX('informe de Gestión 2021-2025'!C:C, MATCH(S85,#REF!, 0), )} -> #REF! | C85: {=INDEX('informe de Gestión 2021-2025'!D:D, MATCH(S85,#REF!, 0), )} -> #REF! | D85: {=INDEX('informe de Gestión 2021-2025'!I:I, MATCH(S85,#REF!, 0), )} -> #REF! | E85: {=INDEX('informe de Gestión 2021-2025'!K:K, MATCH(S85,#REF!, 0), )} -> #REF! | F85: =INDEX(#REF!, MATCH(S85,#REF!, 0), ) -> #REF! | G85: {=INDEX('informe de Gestión 2021-2025'!#REF!, MATCH(S85,#REF!, 0), )} -> #REF! | H85: =INDEX(#REF!, MATCH(S85,#REF!, 0), ) -> #REF! | I85: =INDEX(#REF!, MATCH(S85,#REF!, 0), ) -> #REF! | J85: =INDEX(#REF!, MATCH(S85,#REF!, 0), ) -> #REF! | K85: =INDEX(#REF!, MATCH(S85,#REF!, 0), ) -> #REF! | L85: =INDEX(#REF!, MATCH(S85,#REF!, 0), ) -> #REF! | M85: =INDEX(#REF!, MATCH(S85,#REF!, 0), ) -> #REF! | N85: =INDEX(#REF!, MATCH(S85,#REF!, 0), ) -> #REF! | O85: =INDEX(#REF!, MATCH(S85,#REF!, 0), ) -> #REF! | P85: -6.9244167 | Q85: -76.330917 | R85: 76.33091666666667°W 6.924416666666667°S | S85: R - 84
A86: 85 | B86: {=INDEX('informe de Gestión 2021-2025'!C:C, MATCH(S86,#REF!, 0), )} -> #REF! | C86: {=INDEX('informe de Gestión 2021-2025'!D:D, MATCH(S86,#REF!, 0), )} -> #REF! | D86: {=INDEX('informe de Gestión 2021-2025'!I:I, MATCH(S86,#REF!, 0), )} -> #REF! | E86: {=INDEX('informe de Gestión 2021-2025'!K:K, MATCH(S86,#REF!, 0), )} -> #REF! | F86: =INDEX(#REF!, MATCH(S86,#REF!, 0), ) -> #REF! | G86: {=INDEX('informe de Gestión 2021-2025'!#REF!, MATCH(S86,#REF!, 0), )} -> #REF! | H86: =INDEX(#REF!, MATCH(S86,#REF!, 0), ) -> #REF! | I86: =INDEX(#REF!, MATCH(S86,#REF!, 0), ) -> #REF! | J86: =INDEX(#REF!, MATCH(S86,#REF!, 0), ) -> #REF! | K86: =INDEX(#REF!, MATCH(S86,#REF!, 0), ) -> #REF! | L86: =INDEX(#REF!, MATCH(S86,#REF!, 0), ) -> #REF! | M86: =INDEX(#REF!, MATCH(S86,#REF!, 0), ) -> #REF! | N86: =INDEX(#REF!, MATCH(S86,#REF!, 0), ) -> #REF! | O86: =INDEX(#REF!, MATCH(S86,#REF!, 0), ) -> #REF! | S86: R - 85
A87: 86 | B87: {=INDEX('informe de Gestión 2021-2025'!C:C, MATCH(S87,#REF!, 0), )} -> #REF! | C87: {=INDEX('informe de Gestión 2021-2025'!D:D, MATCH(S87,#REF!, 0), )} -> #REF! | D87: {=INDEX('informe de Gestión 2021-2025'!I:I, MATCH(S87,#REF!, 0), )} -> #REF! | E87: {=INDEX('informe de Gestión 2021-2025'!K:K, MATCH(S87,#REF!, 0), )} -> #REF! | F87: =INDEX(#REF!, MATCH(S87,#REF!, 0), ) -> #REF! | G87: {=INDEX('informe de Gestión 2021-2025'!#REF!, MATCH(S87,#REF!, 0), )} -> #REF! | H87: =INDEX(#REF!, MATCH(S87,#REF!, 0), ) -> #REF! | I87: =INDEX(#REF!, MATCH(S87,#REF!, 0), ) -> #REF! | J87: =INDEX(#REF!, MATCH(S87,#REF!, 0), ) -> #REF! | K87: =INDEX(#REF!, MATCH(S87,#REF!, 0), ) -> #REF! | L87: =INDEX(#REF!, MATCH(S87,#REF!, 0), ) -> #REF! | M87: =INDEX(#REF!, MATCH(S87,#REF!, 0), ) -> #REF! | N87: =INDEX(#REF!, MATCH(S87,#REF!, 0), ) -> #REF! | O87: =INDEX(#REF!, MATCH(S87,#REF!, 0), ) -> #REF! | P87: -8.8637611 | Q87: -77.368547 | R87: 77.36854722222222°W 8.86376111111111°S | S87: R - 86
A88: 87 | B88: {=INDEX('informe de Gestión 2021-2025'!C:C, MATCH(S88,#REF!, 0), )} -> #REF! | C88: {=INDEX('informe de Gestión 2021-2025'!D:D, MATCH(S88,#REF!, 0), )} -> #REF! | D88: {=INDEX('informe de Gestión 2021-2025'!I:I, MATCH(S88,#REF!, 0), )} -> #REF! | E88: {=INDEX('informe de Gestión 2021-2025'!K:K, MATCH(S88,#REF!, 0), )} -> #REF! | F88: =INDEX(#REF!, MATCH(S88,#REF!, 0), ) -> #REF! | G88: {=INDEX('informe de Gestión 2021-2025'!#REF!, MATCH(S88,#REF!, 0), )} -> #REF! | H88: =INDEX(#REF!, MATCH(S88,#REF!, 0), ) -> #REF! | I88: =INDEX(#REF!, MATCH(S88,#REF!, 0), ) -> #REF! | J88: =INDEX(#REF!, MATCH(S88,#REF!, 0), ) -> #REF! | K88: =INDEX(#REF!, MATCH(S88,#REF!, 0), ) -> #REF! | L88: =INDEX(#REF!, MATCH(S88,#REF!, 0), ) -> #REF! | M88: =INDEX(#REF!, MATCH(S88,#REF!, 0), ) -> #REF! | N88: =INDEX(#REF!, MATCH(S88,#REF!, 0), ) -> #REF! | O88: =INDEX(#REF!, MATCH(S88,#REF!, 0), ) -> #REF! | P88: -5.2031444 | Q88: -80.632061 | R88: 80.6320611111111°W 5.203144444444445°S | S88: R - 87
A89: 88 | B89: {=INDEX('informe de Gestión 2021-2025'!C:C, MATCH(S89,#REF!, 0), )} -> #REF! | C89: {=INDEX('informe de Gestión 2021-2025'!D:D, MATCH(S89,#REF!, 0), )} -> #REF! | D89: {=INDEX('informe de Gestión 2021-2025'!I:I, MATCH(S89,#REF!, 0), )} -> #REF! | E89: {=INDEX('informe de Gestión 2021-2025'!K:K, MATCH(S89,#REF!, 0), )} -> #REF! | F89: =INDEX(#REF!, MATCH(S89,#REF!, 0), ) -> #REF! | G89: {=INDEX('informe de Gestión 2021-2025'!#REF!, MATCH(S89,#REF!, 0), )} -> #REF! | H89: =INDEX(#REF!, MATCH(S89,#REF!, 0), ) -> #REF! | I89: =INDEX(#REF!, MATCH(S89,#REF!, 0), ) -> #REF! | J89: =INDEX(#REF!, MATCH(S89,#REF!, 0), ) -> #REF! | K89: =INDEX(#REF!, MATCH(S89,#REF!, 0), ) -> #REF! | L89: =INDEX(#REF!, MATCH(S89,#REF!, 0), ) -> #REF! | M89: =INDEX(#REF!, MATCH(S89,#REF!, 0), ) -> #REF! | N89: =INDEX(#REF!, MATCH(S89,#REF!, 0), ) -> #REF! | O89: =INDEX(#REF!, MATCH(S89,#REF!, 0), ) -> #REF! | P89: -5.13325 | Q89: -80.642639 | R89: 80.6426388888889°W 5.133249999999999°S | S89: R - 88
A90: 89 | B90: {=INDEX('informe de Gestión 2021-2025'!C:C, MATCH(S90,#REF!, 0), )} -> #REF! | C90: {=INDEX('informe de Gestión 2021-2025'!D:D, MATCH(S90,#REF!, 0), )} -> #REF! | D90: {=INDEX('informe de Gestión 2021-2025'!I:I, MATCH(S90,#REF!, 0), )} -> #REF! | E90: {=INDEX('informe de Gestión 2021-2025'!K:K, MATCH(S90,#REF!, 0), )} -> #REF! | F90: =INDEX(#REF!, MATCH(S90,#REF!, 0), ) -> #REF! | G90: {=INDEX('informe de Gestión 2021-2025'!#REF!, MATCH(S90,#REF!, 0), )} -> #REF! | H90: =INDEX(#REF!, MATCH(S90,#REF!, 0), ) -> #REF! | I90: =INDEX(#REF!, MATCH(S90,#REF!, 0), ) -> #REF! | J90: =INDEX(#REF!, MATCH(S90,#REF!, 0), ) -> #REF! | K90: =INDEX(#REF!, MATCH(S90,#REF!, 0), ) -> #REF! | L90: =INDEX(#REF!, MATCH(S90,#REF!, 0), ) -> #REF! | M90: =INDEX(#REF!, MATCH(S90,#REF!, 0), ) -> #REF! | N90: =INDEX(#REF!, MATCH(S90,#REF!, 0), ) -> #REF! | O90: =INDEX(#REF!, MATCH(S90,#REF!, 0), ) -> #REF! | P90: -5.1335278 | Q90: -80.641861 | R90: 80.64186111111111°W 5.133527777777778°S | S90: R - 89
A91: 90 | B91: {=INDEX('informe de Gestión 2021-2025'!C:C, MATCH(S91,#REF!, 0), )} -> #REF! | C91: {=INDEX('informe de Gestión 2021-2025'!D:D, MATCH(S91,#REF!, 0), )} -> #REF! | D91: {=INDEX('informe de Gestión 2021-2025'!I:I, MATCH(S91,#REF!, 0), )} -> #REF! | E91: {=INDEX('informe de Gestión 2021-2025'!K:K, MATCH(S91,#REF!, 0), )} -> #REF! | F91: =INDEX(#REF!, MATCH(S91,#REF!, 0), ) -> #REF! | G91: {=INDEX('informe de Gestión 2021-2025'!#REF!, MATCH(S91,#REF!, 0), )} -> #REF! | H91: =INDEX(#REF!, MATCH(S91,#REF!, 0), ) -> #REF! | I91: =INDEX(#REF!, MATCH(S91,#REF!, 0), ) -> #REF! | J91: =INDEX(#REF!, MATCH(S91,#REF!, 0), ) -> #REF! | K91: =INDEX(#REF!, MATCH(S91,#REF!, 0), ) -> #REF! | L91: =INDEX(#REF!, MATCH(S91,#REF!, 0), ) -> #REF! | M91: =INDEX(#REF!, MATCH(S91,#REF!, 0), ) -> #REF! | N91: =INDEX(#REF!, MATCH(S91,#REF!, 0), ) -> #REF! | O91: =INDEX(#REF!, MATCH(S91,#REF!, 0), ) -> #REF! | P91: -8.8196583 | Q91: -77.467883 | R91: 77.46788333333333°W 8.819658333333333°S | S91: R - 90
A92: 91 | B92: {=INDEX('informe de Gestión 2021-2025'!C:C, MATCH(S92,#REF!, 0), )} -> #REF! | C92: {=INDEX('informe de Gestión 2021-2025'!D:D, MATCH(S92,#REF!, 0), )} -> #REF! | D92: {=INDEX('informe de Gestión 2021-2025'!I:I, MATCH(S92,#REF!, 0), )} -> #REF! | E92: {=INDEX('informe de Gestión 2021-2025'!K:K, MATCH(S92,#REF!, 0), )} -> #REF! | F92: =INDEX(#REF!, MATCH(S92,#REF!, 0), ) -> #REF! | G92: {=INDEX('informe de Gestión 2021-2025'!#REF!, MATCH(S92,#REF!, 0), )} -> #REF! | H92: =INDEX(#REF!, MATCH(S92,#REF!, 0), ) -> #REF! | I92: =INDEX(#REF!, MATCH(S92,#REF!, 0), ) -> #REF! | J92: =INDEX(#REF!, MATCH(S92,#REF!, 0), ) -> #REF! | K92: =INDEX(#REF!, MATCH(S92,#REF!, 0), ) -> #REF! | L92: =INDEX(#REF!, MATCH(S92,#REF!, 0), ) -> #REF! | M92: =INDEX(#REF!, MATCH(S92,#REF!, 0), ) -> #REF! | N92: =INDEX(#REF!, MATCH(S92,#REF!, 0), ) -> #REF! | O92: =INDEX(#REF!, MATCH(S92,#REF!, 0), ) -> #REF! | P92: -8.0590222 | Q92: -78.807583 | R92: 78.80758333333333°W 8.059022222222223°S | S92: R - 91
A93: 92 | B93: {=INDEX('informe de Gestión 2021-2025'!C:C, MATCH(S93,#REF!, 0), )} -> #REF! | C93: {=INDEX('informe de Gestión 2021-2025'!D:D, MATCH(S93,#REF!, 0), )} -> #REF! | D93: {=INDEX('informe de Gestión 2021-2025'!I:I, MATCH(S93,#REF!, 0), )} -> #REF! | E93: {=INDEX('informe de Gestión 2021-2025'!K:K, MATCH(S93,#REF!, 0), )} -> #REF! | F93: =INDEX(#REF!, MATCH(S93,#REF!, 0), ) -> #REF! | G93: {=INDEX('informe de Gestión 2021-2025'!#REF!, MATCH(S93,#REF!, 0), )} -> #REF! | H93: =INDEX(#REF!, MATCH(S93,#REF!, 0), ) -> #REF! | I93: =INDEX(#REF!, MATCH(S93,#REF!, 0), ) -> #REF! | J93: =INDEX(#REF!, MATCH(S93,#REF!, 0), ) -> #REF! | K93: =INDEX(#REF!, MATCH(S93,#REF!, 0), ) -> #REF! | L93: =INDEX(#REF!, MATCH(S93,#REF!, 0), ) -> #REF! | M93: =INDEX(#REF!, MATCH(S93,#REF!, 0), ) -> #REF! | N93: =INDEX(#REF!, MATCH(S93,#REF!, 0), ) -> #REF! | O93: =INDEX(#REF!, MATCH(S93,#REF!, 0), ) -> #REF! | P93: -8.0014833 | Q93: -78.30655 | R93: 78.30655°W 8.001483333333333°S | S93: R - 92
A94: 93 | B94: {=INDEX('informe de Gestión 2021-2025'!C:C, MATCH(S94,#REF!, 0), )} -> #REF! | C94: {=INDEX('informe de Gestión 2021-2025'!D:D, MATCH(S94,#REF!, 0), )} -> #REF! | D94: {=INDEX('informe de Gestión 2021-2025'!I:I, MATCH(S94,#REF!, 0), )} -> #REF! | E94: {=INDEX('informe de Gestión 2021-2025'!K:K, MATCH(S94,#REF!, 0), )} -> #REF! | F94: =INDEX(#REF!, MATCH(S94,#REF!, 0), ) -> #REF! | G94: {=INDEX('informe de Gestión 2021-2025'!#REF!, MATCH(S94,#REF!, 0), )} -> #REF! | H94: =INDEX(#REF!, MATCH(S94,#REF!, 0), ) -> #REF! | I94: =INDEX(#REF!, MATCH(S94,#REF!, 0), ) -> #REF! | J94: =INDEX(#REF!, MATCH(S94,#REF!, 0), ) -> #REF! | K94: =INDEX(#REF!, MATCH(S94,#REF!, 0), ) -> #REF! | L94: =INDEX(#REF!, MATCH(S94,#REF!, 0), ) -> #REF! | M94: =INDEX(#REF!, MATCH(S94,#REF!, 0), ) -> #REF! | N94: =INDEX(#REF!, MATCH(S94,#REF!, 0), ) -> #REF! | O94: =INDEX(#REF!, MATCH(S94,#REF!, 0), ) -> #REF! | P94: -6.3282639 | Q94: -76.761936 | R94: 76.76193611111111°W 6.3282638888888885°S | S94: R - 93
A95: 94 | B95: {=INDEX('informe de Gestión 2021-2025'!C:C, MATCH(S95,#REF!, 0), )} -> #REF! | C95: {=INDEX('informe de Gestión 2021-2025'!D:D, MATCH(S95,#REF!, 0), )} -> #REF! | D95: {=INDEX('informe de Gestión 2021-2025'!I:I, MATCH(S95,#REF!, 0), )} -> #REF! | E95: {=INDEX('informe de Gestión 2021-2025'!K:K, MATCH(S95,#REF!, 0), )} -> #REF! | F95: =INDEX(#REF!, MATCH(S95,#REF!, 0), ) -> #REF! | G95: {=INDEX('informe de Gestión 2021-2025'!#REF!, MATCH(S95,#REF!, 0), )} -> #REF! | H95: =INDEX(#REF!, MATCH(S95,#REF!, 0), ) -> #REF! | I95: =INDEX(#REF!, MATCH(S95,#REF!, 0), ) -> #REF! | J95: =INDEX(#REF!, MATCH(S95,#REF!, 0), ) -> #REF! | K95: =INDEX(#REF!, MATCH(S95,#REF!, 0), ) -> #REF! | L95: =INDEX(#REF!, MATCH(S95,#REF!, 0), ) -> #REF! | M95: =INDEX(#REF!, MATCH(S95,#REF!, 0), ) -> #REF! | N95: =INDEX(#REF!, MATCH(S95,#REF!, 0), ) -> #REF! | O95: =INDEX(#REF!, MATCH(S95,#REF!, 0), ) -> #REF! | P95: -5.1251667 | Q95: -79.01175 | R95: 79.01175°W 5.125166666666666°S | S95: R - 94
A96: 95 | B96: {=INDEX('informe de Gestión 2021-2025'!C:C, MATCH(S96,#REF!, 0), )} -> #REF! | C96: {=INDEX('informe de Gestión 2021-2025'!D:D, MATCH(S96,#REF!, 0), )} -> #REF! | D96: {=INDEX('informe de Gestión 2021-2025'!I:I, MATCH(S96,#REF!, 0), )} -> #REF! | E96: {=INDEX('informe de Gestión 2021-2025'!K:K, MATCH(S96,#REF!, 0), )} -> #REF! | F96: =INDEX(#REF!, MATCH(S96,#REF!, 0), ) -> #REF! | G96: {=INDEX('informe de Gestión 2021-2025'!#REF!, MATCH(S96,#REF!, 0), )} -> #REF! | H96: =INDEX(#REF!, MATCH(S96,#REF!, 0), ) -> #REF! | I96: =INDEX(#REF!, MATCH(S96,#REF!, 0), ) -> #REF! | J96: =INDEX(#REF!, MATCH(S96,#REF!, 0), ) -> #REF! | K96: =INDEX(#REF!, MATCH(S96,#REF!, 0), ) -> #REF! | L96: =INDEX(#REF!, MATCH(S96,#REF!, 0), ) -> #REF! | M96: =INDEX(#REF!, MATCH(S96,#REF!, 0), ) -> #REF! | N96: =INDEX(#REF!, MATCH(S96,#REF!, 0), ) -> #REF! | O96: =INDEX(#REF!, MATCH(S96,#REF!, 0), ) -> #REF! | P96: -4.8468889 | Q96: -80.878194 | R96: 80.87819444444443°W 4.846888888888889°S | S96: R - 95
A97: 96 | B97: {=INDEX('informe de Gestión 2021-2025'!C:C, MATCH(S97,#REF!, 0), )} -> #REF! | C97: {=INDEX('informe de Gestión 2021-2025'!D:D, MATCH(S97,#REF!, 0), )} -> #REF! | D97: {=INDEX('informe de Gestión 2021-2025'!I:I, MATCH(S97,#REF!, 0), )} -> #REF! | E97: {=INDEX('informe de Gestión 2021-2025'!K:K, MATCH(S97,#REF!, 0), )} -> #REF! | F97: =INDEX(#REF!, MATCH(S97,#REF!, 0), ) -> #REF! | G97: {=INDEX('informe de Gestión 2021-2025'!#REF!, MATCH(S97,#REF!, 0), )} -> #REF! | H97: =INDEX(#REF!, MATCH(S97,#REF!, 0), ) -> #REF! | I97: =INDEX(#REF!, MATCH(S97,#REF!, 0), ) -> #REF! | J97: =INDEX(#REF!, MATCH(S97,#REF!, 0), ) -> #REF! | K97: =INDEX(#REF!, MATCH(S97,#REF!, 0), ) -> #REF! | L97: =INDEX(#REF!, MATCH(S97,#REF!, 0), ) -> #REF! | M97: =INDEX(#REF!, MATCH(S97,#REF!, 0), ) -> #REF! | N97: =INDEX(#REF!, MATCH(S97,#REF!, 0), ) -> #REF! | O97: =INDEX(#REF!, MATCH(S97,#REF!, 0), ) -> #REF! | P97: -6.6202778 | Q97: -76.687453 | R97: 76.68745277777778°W 6.620277777777778°S | S97: R - 96
...

Sheet LOGIN
A1: Correo | B1: Contraseña
A2: malvarado@betheltv.tv | B2: MA43
A3: acueto@betheltv.tv | B3: AC23
A4: abautista@betheltv.tv | B4: AB99
A5: iarenas@betheltv.tv | B5: IA01
A6: rcastillo@betheltv.tv | B6: RC51
A7: spurizaca@betheltv.tv | B7: SP07
A8: hunocc@betheltv.tv | B8: HU67
A9: cramos@betheltv.tv | B9: CR66
A10: jespiritu@betheltv.tv | B10: JE01
A11: mlorenzo@betheltv.tv | B11: ML79
A12: rbravo@betheltv.tv | B12: RB51
... A26: Admin | B26: Admin

Sheet LOG
A1: USUARIOS | B1: ULTIMO ACCESO
A2: malvarado@betheltv.tv | B2: 45779.555
A3: rbravo@betheltv.tv | B3: 45779.557
A4: nsilva@betheltv.tv | B4: 45779.557
A5: JESPIritu@betheltv.tv | B5: 45779.565
A6: cpanduro@betheltv.tv | B6: 45779.599
A7: malvarado@betheltv.tv | B7: 45780.411
A8: malvarado@betheltv.tv | B8: 45780.433
A9: malvarado@betheltv.tv | B9: 45780.445
A10: malvarado@betheltv.tv | B10: 45780.453
A11: malvarado@betheltv.tv | B11: 45780.553
A12: malvarado@betheltv.tv | B12: 45780.579
A13: malvarado@betheltv.tv | B13: 45780.621
... A186: Admin | B186: 45985.68
