Workbook

Sheet NORTE - RUTH
B1: LOCALIDAD | C1: DEPARTAMENTO | D1: BANDA | E1: FREC. | F1: PRESBITERIO | G1: ESTADO | H1: INCIDENCIAS | I1: ULTIMA ACTUALIZACION | J1: OBSERVACIONES | K1: ID | L1: RESPONSABLE | M1: NIVEL | N1: PRESUP S/. | O1: PRESUP $ | P1: Fecha F.A | Q1: Tiempo F.A | R1: RENOVACION
A2: 3 | B2: Amotape | C2: Piura | D2: VHF | E2: 9 | F2: 105 | G2: A.A | H2: AMOTAPE | I2: 21/11/2025 - Sectoristas - Se envió al pastor el presupuesto para compra de implementos para mantenimiento de torre el día lunes 17 de noviembre, señalo por motivo de salud de su esposa no podrá atenderlo por ahora. | K2: ="R - "&A2 -> R - 3 | L2: Sectoristas | M2: Nivel 1 | Q2: =IF(P2="","-", IF(DATEDIF(P2,TODAY(),"Y")=0,"",IF(DATEDIF(P2,TODAY(),"Y")=1,DATEDIF(P2,TODAY(),"Y")&" año con ",DATEDIF(P2,TODAY(),"Y")&" años con "))&IF(DATEDIF(P2,TODAY(),"YM")=0,"",IF(DATEDIF(P2,TODAY(),"YM")=1,DATEDIF(P2,TODAY(),"YM")&" mes y ",DATEDIF(P2,TODAY(),"YM")&" meses y "))&IF(DATEDIF(P2,TODAY(),"MD")=0,"",IF(DATEDIF(P2,TODAY(),"MD")=1,DATEDIF(P2,TODAY(),"MD")&" día",DATEDIF(P2,TODAY(),"MD")&" días"))) -> -
A3: 4 | B3: Ayabaca | C3: Piura | D3: FM | E3: 96.9 | F3: 153 | G3: A.A | H3: AYABACA | I3: 1/12/2025 - Sectoristas - Con fecha de ayer domingo 30 de noviembre el pastor envía videos donde se corrobora la operatividad de la radio y el canal. | K3: ="R - "&A3 -> R - 4 | L3: Sectoristas | M3: Nivel 1 | Q3: =IF(P3="","-", IF(DATEDIF(P3,TODAY(),"Y")=0,"",IF(DATEDIF(P3,TODAY(),"Y")=1,DATEDIF(P3,TODAY(),"Y")&" año con ",DATEDIF(P3,TODAY(),"Y")&" años con "))&IF(DATEDIF(P3,TODAY(),"YM")=0,"",IF(DATEDIF(P3,TODAY(),"YM")=1,DATEDIF(P3,TODAY(),"YM")&" mes y ",DATEDIF(P3,TODAY(),"YM")&" meses y "))&IF(DATEDIF(P3,TODAY(),"MD")=0,"",IF(DATEDIF(P3,TODAY(),"MD")=1,DATEDIF(P3,TODAY(),"MD")&" día",DATEDIF(P3,TODAY(),"MD")&" días"))) -> -
A4: 5 | B4: Ayabaca | C4: Piura | D4: VHF | E4: 2 | F4: 153 | G4: A.A | H4: AYABACA | I4: 1/12/2025 - Sectoristas - Con fecha de ayer domingo 30 de noviembre el pastor envía videos donde se corrobora la operatividad de la radio y el canal. | K4: ="R - "&A4 -> R - 5 | L4: Sectoristas | M4: Nivel 1 | Q4: =IF(P4="","-", IF(DATEDIF(P4,TODAY(),"Y")=0,"",IF(DATEDIF(P4,TODAY(),"Y")=1,DATEDIF(P4,TODAY(),"Y")&" año con ",DATEDIF(P4,TODAY(),"Y")&" años con "))&IF(DATEDIF(P4,TODAY(),"YM")=0,"",IF(DATEDIF(P4,TODAY(),"YM")=1,DATEDIF(P4,TODAY(),"YM")&" mes y ",DATEDIF(P4,TODAY(),"YM")&" meses y "))&IF(DATEDIF(P4,TODAY(),"MD")=0,"",IF(DATEDIF(P4,TODAY(),"MD")=1,DATEDIF(P4,TODAY(),"MD")&" día",DATEDIF(P4,TODAY(),"MD")&" días"))) -> -
A5: 7 | B5: Bagua - La Peca | C5: Amazonas | D5: UHF | E5: 19 | F5: 77 | G5: A.A | H5: BAGUA | I5: 4/11/2025 - Sectoristas - Al aire | K5: ="R - "&A5 -> R - 7 | Q5: =IF(P5="","-", IF(DATEDIF(P5,TODAY(),"Y")=0,"",IF(DATEDIF(P5,TODAY(),"Y")=1,DATEDIF(P5,TODAY(),"Y")&" año con ",DATEDIF(P5,TODAY(),"Y")&" años con "))&IF(DATEDIF(P5,TODAY(),"YM")=0,"",IF(DATEDIF(P5,TODAY(),"YM")=1,DATEDIF(P5,TODAY(),"YM")&" mes y ",DATEDIF(P5,TODAY(),"YM")&" meses y "))&IF(DATEDIF(P5,TODAY(),"MD")=0,"",IF(DATEDIF(P5,TODAY(),"MD")=1,DATEDIF(P5,TODAY(),"MD")&" día",DATEDIF(P5,TODAY(),"MD")&" días"))) -> -
A6: 6 | B6: Bagua - La Peca | C6: Amazonas | D6: FM | E6: 93.1 | F6: 77 | G6: A.A | H6: BAGUA FM | I6: 27/11/2025 - Sectoristas - Con fecha martes 25 de noviembre el pastor envía evidencia en video donde sintoniza la radio. | J6: 04/11/2025 Según información brindada por Gregorio se conectó el transmisor de la radio pero con un estabilizador de computadora pues su estabilizador esta quemado. | K6: ="R - "&A6 -> R - 6 | L6: Sectoristas | M6: Nivel 1 | Q6: =IF(P6="","-", IF(DATEDIF(P6,TODAY(),"Y")=0,"",IF(DATEDIF(P6,TODAY(),"Y")=1,DATEDIF(P6,TODAY(),"Y")&" año con ",DATEDIF(P6,TODAY(),"Y")&" años con "))&IF(DATEDIF(P6,TODAY(),"YM")=0,"",IF(DATEDIF(P6,TODAY(),"YM")=1,DATEDIF(P6,TODAY(),"YM")&" mes y ",DATEDIF(P6,TODAY(),"YM")&" meses y "))&IF(DATEDIF(P6,TODAY(),"MD")=0,"",IF(DATEDIF(P6,TODAY(),"MD")=1,DATEDIF(P6,TODAY(),"MD")&" día",DATEDIF(P6,TODAY(),"MD")&" días"))) -> -
A7: 8 | B7: Bagua Grande | C7: Amazonas | D7: FM | E7: 92.5 | F7: 148 | G7: A.A | H7: BAGUA GRANDE | I7: 1/12/2025 - Sectoristas - Con fecha sábado 29 de noviembre el pastor local señala que la radio se encuentra operativa enviando videos. | K7: ="R - "&A7 -> R - 8 | L7: Sectoristas | M7: Nivel 1 | Q7: =IF(P7="","-", IF(DATEDIF(P7,TODAY(),"Y")=0,"",IF(DATEDIF(P7,TODAY(),"Y")=1,DATEDIF(P7,TODAY(),"Y")&" año con ",DATEDIF(P7,TODAY(),"Y")&" años con "))&IF(DATEDIF(P7,TODAY(),"YM")=0,"",IF(DATEDIF(P7,TODAY(),"YM")=1,DATEDIF(P7,TODAY(),"YM")&" mes y ",DATEDIF(P7,TODAY(),"YM")&" meses y "))&IF(DATEDIF(P7,TODAY(),"MD")=0,"",IF(DATEDIF(P7,TODAY(),"MD")=1,DATEDIF(P7,TODAY(),"MD")&" día",DATEDIF(P7,TODAY(),"MD")&" días"))) -> -
A8: 9 | B8: Bambamarca | C8: Cajamarca | D8: FM | E8: 89.7 | F8: 69 | G8: A.A | H8: BAMBAMARCA | I8: 27/11/2025 - Sectoristas - Con fecha martes 25 de noviembre el pastor local señala que la radio se encuentra al aire, pero NO envia video de evidencia. | K8: ="R - "&A8 -> R - 9 | L8: Sectoristas | M8: Nivel 1 | Q8: =IF(P8="","-", IF(DATEDIF(P8,TODAY(),"Y")=0,"",IF(DATEDIF(P8,TODAY(),"Y")=1,DATEDIF(P8,TODAY(),"Y")&" año con ",DATEDIF(P8,TODAY(),"Y")&" años con "))&IF(DATEDIF(P8,TODAY(),"YM")=0,"",IF(DATEDIF(P8,TODAY(),"YM")=1,DATEDIF(P8,TODAY(),"YM")&" mes y ",DATEDIF(P8,TODAY(),"YM")&" meses y "))&IF(DATEDIF(P8,TODAY(),"MD")=0,"",IF(DATEDIF(P8,TODAY(),"MD")=1,DATEDIF(P8,TODAY(),"MD")&" día",DATEDIF(P8,TODAY(),"MD")&" días"))) -> -
A9: 10 | B9: Cabana | C9: Ancash | D9: FM | E9: 92.9 | F9: 53 | G9: A.A | H9: CABANA | I9: 1/12/2025 - Sectoristas - Con fecha jueves 27 de noviembre el pastor confirma que la radio se encuentra operativa enviando un video donde muestra la sintonia. | K9: ="R - "&A9 -> R - 10 | L9: Sectoristas | M9: Nivel 1 | Q9: =IF(P9="","-", IF(DATEDIF(P9,TODAY(),"Y")=0,"",IF(DATEDIF(P9,TODAY(),"Y")=1,DATEDIF(P9,TODAY(),"Y")&" año con ",DATEDIF(P9,TODAY(),"Y")&" años con "))&IF(DATEDIF(P9,TODAY(),"YM")=0,"",IF(DATEDIF(P9,TODAY(),"YM")=1,DATEDIF(P9,TODAY(),"YM")&" mes y ",DATEDIF(P9,TODAY(),"YM")&" meses y "))&IF(DATEDIF(P9,TODAY(),"MD")=0,"",IF(DATEDIF(P9,TODAY(),"MD")=1,DATEDIF(P9,TODAY(),"MD")&" día",DATEDIF(P9,TODAY(),"MD")&" días"))) -> -
A10: 11 | B10: Cabana | C10: Ancash | D10: VHF | E10: 9 | F10: 53 | G10: A.A | H10: CABANA | I10: 27/11/2025 - Sectoristas - Con fecha martes 25 de noviembre el pastor envía como evidencia video donde se visualiza la sintonía del canal. Falto que envie de radio. | K10: ="R - "&A10 -> R - 11 | L10: Sectoristas | M10: Nivel 1 | Q10: =IF(P10="","-", IF(DATEDIF(P10,TODAY(),"Y")=0,"",IF(DATEDIF(P10,TODAY(),"Y")=1,DATEDIF(P10,TODAY(),"Y")&" año con ",DATEDIF(P10,TODAY(),"Y")&" años con "))&IF(DATEDIF(P10,TODAY(),"YM")=0,"",IF(DATEDIF(P10,TODAY(),"YM")=1,DATEDIF(P10,TODAY(),"YM")&" mes y ",DATEDIF(P10,TODAY(),"YM")&" meses y "))&IF(DATEDIF(P10,TODAY(),"MD")=0,"",IF(DATEDIF(P10,TODAY(),"MD")=1,DATEDIF(P10,TODAY(),"MD")&" día",DATEDIF(P10,TODAY(),"MD")&" días"))) -> -
A11: 12 | B11: Cajabamba | C11: Cajabamba | D11: FM | E11: 106.5 | F11: 26 | G11: A.A | H11: CAJABAMBA | I11: 4/12/2025 - Sectoristas - Con fecha lunes 01 de diciembre el pastor envia video evidenciando la operatividad | K11: ="R - "&A11 -> R - 12 | L11: Sectoristas | M11: Nivel 1 | Q11: =IF(P11="","-", IF(DATEDIF(P11,TODAY(),"Y")=0,"",IF(DATEDIF(P11,TODAY(),"Y")=1,DATEDIF(P11,TODAY(),"Y")&" año con ",DATEDIF(P11,TODAY(),"Y")&" años con "))&IF(DATEDIF(P11,TODAY(),"YM")=0,"",IF(DATEDIF(P11,TODAY(),"YM")=1,DATEDIF(P11,TODAY(),"YM")&" mes y ",DATEDIF(P11,TODAY(),"YM")&" meses y "))&IF(DATEDIF(P11,TODAY(),"MD")=0,"",IF(DATEDIF(P11,TODAY(),"MD")=1,DATEDIF(P11,TODAY(),"MD")&" día",DATEDIF(P11,TODAY(),"MD")&" días"))) -> -
A12: 13 | B12: Cajamarca | C12: Cajamarca | D12: UHF | E12: 47 | F12: 26 | G12: A.A | H12: CAJAMARCA | I12: 10/11/2025 - Ingeniería - Se restableció nuevamente el fluido eléctrico por tema de mantenimiento de la empresa eléctrica. Se puso nuevamente al aire. | J12: 04/11/2025 El pastor local señalo el día jueves 30 de octubre que las estaciones estarían fuera del aire una semana | K12: ="R - "&A12 -> R - 13 | L12: Ingeniería | M12: Nivel 1 | Q12: =IF(P12="","-", IF(DATEDIF(P12,TODAY(),"Y")=0,"",IF(DATEDIF(P12,TODAY(),"Y")=1,DATEDIF(P12,TODAY(),"Y")&" año con ",DATEDIF(P12,TODAY(),"Y")&" años con "))&IF(DATEDIF(P12,TODAY(),"YM")=0,"",IF(DATEDIF(P12,TODAY(),"YM")=1,DATEDIF(P12,TODAY(),"YM")&" mes y ",DATEDIF(P12,TODAY(),"YM")&" meses y "))&IF(DATEDIF(P12,TODAY(),"MD")=0,"",IF(DATEDIF(P12,TODAY(),"MD")=1,DATEDIF(P12,TODAY(),"MD")&" día",DATEDIF(P12,TODAY(),"MD")&" días"))) -> -
A13: 14 | B13: Cajamarca | C13: Cajamarca | D13: FM | E13: 104.5 | F13: 26 | G13: A.A | H13: CAJAMARCA | I13: 11/11/2025 - Ingeniería - Se restableció nuevamente el fluido eléctrico por tema de mantenimiento de la empresa eléctrica. Se puso nuevamente al aire. | J13: 04/11/2025 El pastor local señalo el día jueves 30 de octubre que las estaciones estarían fuera del aire una semana | K13: ="R - "&A13 -> R - 14 | L13: Sectoristas | M13: Nivel 1 | Q13: =IF(P13="","-", IF(DATEDIF(P13,TODAY(),"Y")=0,"",IF(DATEDIF(P13,TODAY(),"Y")=1,DATEDIF(P13,TODAY(),"Y")&" año con ",DATEDIF(P13,TODAY(),"Y")&" años con "))&IF(DATEDIF(P13,TODAY(),"YM")=0,"",IF(DATEDIF(P13,TODAY(),"YM")=1,DATEDIF(P13,TODAY(),"YM")&" mes y ",DATEDIF(P13,TODAY(),"YM")&" meses y "))&IF(DATEDIF(P13,TODAY(),"MD")=0,"",IF(DATEDIF(P13,TODAY(),"MD")=1,DATEDIF(P13,TODAY(),"MD")&" día",DATEDIF(P13,TODAY(),"MD")&" días"))) -> -
A14: 15 | B14: Callayuc | C14: Cajamarca | D14: FM | E14: 92.5 | F14: 83 | G14: A.A | H14: CALLAYUC | I14: 3/11/2025 - Sectoristas - Con fecha 01 de noviembre el pastor local y el hno Gregorio confirman que la radio se encuentra operativa asimismo enviaron audio como evidencia | K14: ="R - "&A14 -> R - 15 | Q14: =IF(P14="","-", IF(DATEDIF(P14,TODAY(),"Y")=0,"",IF(DATEDIF(P14,TODAY(),"Y")=1,DATEDIF(P14,TODAY(),"Y")&" año con ",DATEDIF(P14,TODAY(),"Y")&" años con "))&IF(DATEDIF(P14,TODAY(),"YM")=0,"",IF(DATEDIF(P14,TODAY(),"YM")=1,DATEDIF(P14,TODAY(),"YM")&" mes y ",DATEDIF(P14,TODAY(),"YM")&" meses y "))&IF(DATEDIF(P14,TODAY(),"MD")=0,"",IF(DATEDIF(P14,TODAY(),"MD")=1,DATEDIF(P14,TODAY(),"MD")&" día",DATEDIF(P14,TODAY(),"MD")&" días"))) -> -
A15: 16 | B15: Campanilla | C15: San Martin | D15: FM | E15: 91.7 | F15: 78 | G15: A.A | H15: CAMPANILLA | I15: 9/10/2025 - Sectoristas - El día de hoy jueves 09 de octubre el pastor local señala que la radio se encuentra operativa las 24 horas, el pastor envió video evidenciando la operatividad. Asimismo, se le envió mensaje orientando sobre la renovacion de autorizacion | J15: 31/01/2025 El pastor comunico eo dia de hoy que nuevamente se encuentra operativa | K15: ="R - "&A15 -> R - 16 | Q15: =IF(P15="","-", IF(DATEDIF(P15,TODAY(),"Y")=0,"",IF(DATEDIF(P15,TODAY(),"Y")=1,DATEDIF(P15,TODAY(),"Y")&" año con ",DATEDIF(P15,TODAY(),"Y")&" años con "))&IF(DATEDIF(P15,TODAY(),"YM")=0,"",IF(DATEDIF(P15,TODAY(),"YM")=1,DATEDIF(P15,TODAY(),"YM")&" mes y ",DATEDIF(P15,TODAY(),"YM")&" meses y "))&IF(DATEDIF(P15,TODAY(),"MD")=0,"",IF(DATEDIF(P15,TODAY(),"MD")=1,DATEDIF(P15,TODAY(),"MD")&" día",DATEDIF(P15,TODAY(),"MD")&" días"))) -> -
A16: 17 | B16: Caraz | C16: Ancash | D16: FM | E16: 106.1 | F16: 144 | G16: A.A | H16: CARAZ | I16: 21/10/2025 - Sectoristas - Con fecha jueves 16 de octubre el pastor local señal que la radio y el canal se encuentran operativos | K16: ="R - "&A16 -> R - 17 | Q16: =IF(P16="","-", IF(DATEDIF(P16,TODAY(),"Y")=0,"",IF(DATEDIF(P16,TODAY(),"Y")=1,DATEDIF(P16,TODAY(),"Y")&" año con ",DATEDIF(P16,TODAY(),"Y")&" años con "))&IF(DATEDIF(P16,TODAY(),"YM")=0,"",IF(DATEDIF(P16,TODAY(),"YM")=1,DATEDIF(P16,TODAY(),"YM")&" mes y ",DATEDIF(P16,TODAY(),"YM")&" meses y "))&IF(DATEDIF(P16,TODAY(),"MD")=0,"",IF(DATEDIF(P16,TODAY(),"MD")=1,DATEDIF(P16,TODAY(),"MD")&" día",DATEDIF(P16,TODAY(),"MD")&" días"))) -> -
A17: 18 | B17: Caraz | C17: Ancash | D17: VHF | E17: 12 | F17: 144 | G17: A.A | H17: CARAZ | I17: 21/10/2025 - Sectoristas - Con fecha jueves 16 de octubre el pastor local señal que la radio y el canal se encuentran operativos | K17: ="R - "&A17 -> R - 18 | Q17: =IF(P17="","-", IF(DATEDIF(P17,TODAY(),"Y")=0,"",IF(DATEDIF(P17,TODAY(),"Y")=1,DATEDIF(P17,TODAY(),"Y")&" año con ",DATEDIF(P17,TODAY(),"Y")&" años con "))&IF(DATEDIF(P17,TODAY(),"YM")=0,"",IF(DATEDIF(P17,TODAY(),"YM")=1,DATEDIF(P17,TODAY(),"YM")&" mes y ",DATEDIF(P17,TODAY(),"YM")&" meses y "))&IF(DATEDIF(P17,TODAY(),"MD")=0,"",IF(DATEDIF(P17,TODAY(),"MD")=1,DATEDIF(P17,TODAY(),"MD")&" día",DATEDIF(P17,TODAY(),"MD")&" días"))) -> -
A18: 19 | B18: Casa Grande | C18: La Libertad | D18: FM | E18: 90.7 | F18: 130 | G18: A.A | H18: CASA GRANDE | I18: 27/11/2025 - Sectoristas - Con fecha 25 de noviembre el pastor envía audio donde se verifica la operatividad de la radio | K18: ="R - "&A18 -> R - 19 | L18: Sectoristas | M18: Nivel 1 | Q18: =IF(P18="","-", IF(DATEDIF(P18,TODAY(),"Y")=0,"",IF(DATEDIF(P18,TODAY(),"Y")=1,DATEDIF(P18,TODAY(),"Y")&" año con ",DATEDIF(P18,TODAY(),"Y")&" años con "))&IF(DATEDIF(P18,TODAY(),"YM")=0,"",IF(DATEDIF(P18,TODAY(),"YM")=1,DATEDIF(P18,TODAY(),"YM")&" mes y ",DATEDIF(P18,TODAY(),"YM")&" meses y "))&IF(DATEDIF(P18,TODAY(),"MD")=0,"",IF(DATEDIF(P18,TODAY(),"MD")=1,DATEDIF(P18,TODAY(),"MD")&" día",DATEDIF(P18,TODAY(),"MD")&" días"))) -> -
A19: 20 | B19: Casma | C19: Ancash | D19: FM | E19: 101.7 | F19: 95 | G19: A.A | H19: CASMA | I19: 27/11/2025 - Sectoristas - El dia de hoy jueves 27 de noviembre el pastor local envía video evidenciando que la radio se encuentra con señal al aire. | J19: Homologacion transmisor nuevo | K19: ="R - "&A19 -> R - 20 | L19: Sectoristas | M19: Nivel 1 | Q19: =IF(P19="","-", IF(DATEDIF(P19,TODAY(),"Y")=0,"",IF(DATEDIF(P19,TODAY(),"Y")=1,DATEDIF(P19,TODAY(),"Y")&" año con ",DATEDIF(P19,TODAY(),"Y")&" años con "))&IF(DATEDIF(P19,TODAY(),"YM")=0,"",IF(DATEDIF(P19,TODAY(),"YM")=1,DATEDIF(P19,TODAY(),"YM")&" mes y ",DATEDIF(P19,TODAY(),"YM")&" meses y "))&IF(DATEDIF(P19,TODAY(),"MD")=0,"",IF(DATEDIF(P19,TODAY(),"MD")=1,DATEDIF(P19,TODAY(),"MD")&" día",DATEDIF(P19,TODAY(),"MD")&" días"))) -> -
A20: 21 | B20: Celendin | C20: Cajamarca | D20: VHF | E20: 4 | F20: 26 | G20: A.A | H20: CELENDIN | I20: 10/10/2025 - Sectoristas - Con fecha 01 de octubre el pastor local señala que la radio y televisión se encuentran con señal al aire. Estuvieron operativos también en setiembre. | K20: ="R - "&A20 -> R - 21 | Q20: =IF(P20="","-", IF(DATEDIF(P20,TODAY(),"Y")=0,"",IF(DATEDIF(P20,TODAY(),"Y")=1,DATEDIF(P20,TODAY(),"Y")&" año con ",DATEDIF(P20,TODAY(),"Y")&" años con "))&IF(DATEDIF(P20,TODAY(),"YM")=0,"",IF(DATEDIF(P20,TODAY(),"YM")=1,DATEDIF(P20,TODAY(),"YM")&" mes y ",DATEDIF(P20,TODAY(),"YM")&" meses y "))&IF(DATEDIF(P20,TODAY(),"MD")=0,"",IF(DATEDIF(P20,TODAY(),"MD")=1,DATEDIF(P20,TODAY(),"MD")&" día",DATEDIF(P20,TODAY(),"MD")&" días"))) -> -
A21: 22 | B21: Celendin | C21: Cajamarca | D21: FM | E21: 94.9 | F21: 26 | G21: A.A | H21: CELENDIN | I21: 10/10/2025 - Sectoristas - Con fecha 01 de octubre el pastor local señala que la radio y televisión se encuentran con señal al aire. Estuvieron operativos también en setiembre. | K21: ="R - "&A21 -> R - 22 | Q21: =IF(P21="","-", IF(DATEDIF(P21,TODAY(),"Y")=0,"",IF(DATEDIF(P21,TODAY(),"Y")=1,DATEDIF(P21,TODAY(),"Y")&" año con ",DATEDIF(P21,TODAY(),"Y")&" años con "))&IF(DATEDIF(P21,TODAY(),"YM")=0,"",IF(DATEDIF(P21,TODAY(),"YM")=1,DATEDIF(P21,TODAY(),"YM")&" mes y ",DATEDIF(P21,TODAY(),"YM")&" meses y "))&IF(DATEDIF(P21,TODAY(),"MD")=0,"",IF(DATEDIF(P21,TODAY(),"MD")=1,DATEDIF(P21,TODAY(),"MD")&" día",DATEDIF(P21,TODAY(),"MD")&" días"))) -> -
A22: 23 | B22: Chacas | C22: Ancash | D22: FM | E22: 93.7 | F22: 152 | G22: A.A | H22: CHACAS | I22: 27/11/2025 - Sectoristas - Con fecha de hoy 27 de noviembre el pastor local envia video evidenciando la operatividad de la radio | K22: ="R - "&A22 -> R - 23 | L22: Sectoristas | M22: Nivel 1 | Q22: =IF(P22="","-", IF(DATEDIF(P22,TODAY(),"Y")=0,"",IF(DATEDIF(P22,TODAY(),"Y")=1,DATEDIF(P22,TODAY(),"Y")&" año con ",DATEDIF(P22,TODAY(),"Y")&" años con "))&IF(DATEDIF(P22,TODAY(),"YM")=0,"",IF(DATEDIF(P22,TODAY(),"YM")=1,DATEDIF(P22,TODAY(),"YM")&" mes y ",DATEDIF(P22,TODAY(),"YM")&" meses y "))&IF(DATEDIF(P22,TODAY(),"MD")=0,"",IF(DATEDIF(P22,TODAY(),"MD")=1,DATEDIF(P22,TODAY(),"MD")&" día",DATEDIF(P22,TODAY(),"MD")&" días"))) -> -
A23: 24 | B23: Chachapoyas | C23: Amazonas | D23: FM | E23: 94.3 | F23: 33 | G23: A.A | H23: CHACHAPOYAS | I23: 31/10/2025 - Sectoristas - Con fecha 29 de octubre se solicita al pastor Rolando que confirme operatividad, que envíe un audio para verificar si sale señal de la radio y se le consulta si desactivo el timer, señalando que esta operando como se le solicito | K23: ="R - "&A23 -> R - 24 | Q23: =IF(P23="","-", IF(DATEDIF(P23,TODAY(),"Y")=0,"",IF(DATEDIF(P23,TODAY(),"Y")=1,DATEDIF(P23,TODAY(),"Y")&" año con ",DATEDIF(P23,TODAY(),"Y")&" años con "))&IF(DATEDIF(P23,TODAY(),"YM")=0,"",IF(DATEDIF(P23,TODAY(),"YM")=1,DATEDIF(P23,TODAY(),"YM")&" mes y ",DATEDIF(P23,TODAY(),"YM")&" meses y "))&IF(DATEDIF(P23,TODAY(),"MD")=0,"",IF(DATEDIF(P23,TODAY(),"MD")=1,DATEDIF(P23,TODAY(),"MD")&" día",DATEDIF(P23,TODAY(),"MD")&" días"))) -> -
A24: 25 | B24: Chalaco | C24: Piura | D24: FM | E24: 99.9 | F24: 142 | G24: A.A | H24: CHALACO | I24: 20/11/2025 - Ingeniería - Con el apoyo local de un hermano de la zona, se logró poner nuevamente operativa la estación en el Caserío Lanche, ubicación autorizada. | K24: ="R - "&A24 -> R - 25 | Q24: =IF(P24="","-", IF(DATEDIF(P24,TODAY(),"Y")=0,"",IF(DATEDIF(P24,TODAY(),"Y")=1,DATEDIF(P24,TODAY(),"Y")&" año con ",DATEDIF(P24,TODAY(),"Y")&" años con "))&IF(DATEDIF(P24,TODAY(),"YM")=0,"",IF(DATEDIF(P24,TODAY(),"YM")=1,DATEDIF(P24,TODAY(),"YM")&" mes y ",DATEDIF(P24,TODAY(),"YM")&" meses y "))&IF(DATEDIF(P24,TODAY(),"MD")=0,"",IF(DATEDIF(P24,TODAY(),"MD")=1,DATEDIF(P24,TODAY(),"MD")&" día",DATEDIF(P24,TODAY(),"MD")&" días"))) -> -
A25: 28 | B25: Chepén | C25: La Libertad | D25: FM | E25: 90.5 | F25: 54 | G25: A.A | H25: CHEPEN | I25: 4/12/2025 - Sectoristas - Con fecha de hoy 04 de diciembre el hno Walter envía videos para evidenciar la señal de radio y televisión | K25: ="R - "&A25 -> R - 28 | L25: Sectoristas | M25: Nivel 1 | Q25: =IF(P25="","-", IF(DATEDIF(P25,TODAY(),"Y")=0,"",IF(DATEDIF(P25,TODAY(),"Y")=1,DATEDIF(P25,TODAY(),"Y")&" año con ",DATEDIF(P25,TODAY(),"Y")&" años con "))&IF(DATEDIF(P25,TODAY(),"YM")=0,"",IF(DATEDIF(P25,TODAY(),"YM")=1,DATEDIF(P25,TODAY(),"YM")&" mes y ",DATEDIF(P25,TODAY(),"YM")&" meses y "))&IF(DATEDIF(P25,TODAY(),"MD")=0,"",IF(DATEDIF(P25,TODAY(),"MD")=1,DATEDIF(P25,TODAY(),"MD")&" día",DATEDIF(P25,TODAY(),"MD")&" días"))) -> -
A26: 29 | B26: Chepén | C26: La Libertad | D26: VHF | E26: 4 | F26: 54 | G26: A.A | H26: CHEPÉN | I26: 4/12/2025 - Sectoristas - Con fecha de hoy 04 de diciembre el hno Walter envía videos para evidenciar la señal de radio y televisión | K26: ="R - "&A26 -> R - 29 | L26: Sectoristas | M26: Nivel 1 | Q26: =IF(P26="","-", IF(DATEDIF(P26,TODAY(),"Y")=0,"",IF(DATEDIF(P26,TODAY(),"Y")=1,DATEDIF(P26,TODAY(),"Y")&" año con ",DATEDIF(P26,TODAY(),"Y")&" años con "))&IF(DATEDIF(P26,TODAY(),"YM")=0,"",IF(DATEDIF(P26,TODAY(),"YM")=1,DATEDIF(P26,TODAY(),"YM")&" mes y ",DATEDIF(P26,TODAY(),"YM")&" meses y "))&IF(DATEDIF(P26,TODAY(),"MD")=0,"",IF(DATEDIF(P26,TODAY(),"MD")=1,DATEDIF(P26,TODAY(),"MD")&" día",DATEDIF(P26,TODAY(),"MD")&" días"))) -> -
A27: 30 | B27: Chiclayo | C27: Lambayeque | D27: UHF | E27: 43 | F27: 4 | G27: A.A | H27: CHICLAYO | I27: 27/11/2025 - Sectoristas - El dia de ayer 26 de noviembre el pastor Vilcarima señalo que las dos frecuencias de radio y el canal se encuentran operativos, no se le solicito video. | K27: ="R - "&A27 -> R - 30 | L27: Sectoristas | M27: Nivel 1 | Q27: =IF(P27="","-", IF(DATEDIF(P27,TODAY(),"Y")=0,"",IF(DATEDIF(P27,TODAY(),"Y")=1,DATEDIF(P27,TODAY(),"Y")&" año con ",DATEDIF(P27,TODAY(),"Y")&" años con "))&IF(DATEDIF(P27,TODAY(),"YM")=0,"",IF(DATEDIF(P27,TODAY(),"YM")=1,DATEDIF(P27,TODAY(),"YM")&" mes y ",DATEDIF(P27,TODAY(),"YM")&" meses y "))&IF(DATEDIF(P27,TODAY(),"MD")=0,"",IF(DATEDIF(P27,TODAY(),"MD")=1,DATEDIF(P27,TODAY(),"MD")&" día",DATEDIF(P27,TODAY(),"MD")&" días"))) -> -
A28: 32 | B28: Chiclayo - San Jose | C28: Lambayeque | D28: AM | E28: 1280 | F28: 4 | G28: A.A | H28: CHICLAYO | I28: 27/11/2025 - Sectoristas - El dia de ayer 26 de noviembre el pastor Vilcarima señalo que las dos frecuencias de radio y el canal se encuentran operativos, no se le solicito video. | K28: ="R - "&A28 -> R - 32 | L28: Sectoristas | M28: Nivel 1 | Q28: =IF(P28="","-", IF(DATEDIF(P28,TODAY(),"Y")=0,"",IF(DATEDIF(P28,TODAY(),"Y")=1,DATEDIF(P28,TODAY(),"Y")&" año con ",DATEDIF(P28,TODAY(),"Y")&" años con "))&IF(DATEDIF(P28,TODAY(),"YM")=0,"",IF(DATEDIF(P28,TODAY(),"YM")=1,DATEDIF(P28,TODAY(),"YM")&" mes y ",DATEDIF(P28,TODAY(),"YM")&" meses y "))&IF(DATEDIF(P28,TODAY(),"MD")=0,"",IF(DATEDIF(P28,TODAY(),"MD")=1,DATEDIF(P28,TODAY(),"MD")&" día",DATEDIF(P28,TODAY(),"MD")&" días"))) -> -
A29: 31 | B29: Chiclayo | C29: Lambayeque | D29: FM | E29: 107.7 | F29: 4 | G29: A.A | H29: CHICLAYO FM | I29: 27/11/2025 - Sectoristas - El dia de ayer 26 de noviembre el pastor Vilcarima señalo que las dos frecuencias de radio y el canal se encuentran operativos, no se le solicito video. | K29: ="R - "&A29 -> R - 31 | L29: Sectoristas | M29: Nivel 1 | Q29: =IF(P29="","-", IF(DATEDIF(P29,TODAY(),"Y")=0,"",IF(DATEDIF(P29,TODAY(),"Y")=1,DATEDIF(P29,TODAY(),"Y")&" año con ",DATEDIF(P29,TODAY(),"Y")&" años con "))&IF(DATEDIF(P29,TODAY(),"YM")=0,"",IF(DATEDIF(P29,TODAY(),"YM")=1,DATEDIF(P29,TODAY(),"YM")&" mes y ",DATEDIF(P29,TODAY(),"YM")&" meses y "))&IF(DATEDIF(P29,TODAY(),"MD")=0,"",IF(DATEDIF(P29,TODAY(),"MD")=1,DATEDIF(P29,TODAY(),"MD")&" día",DATEDIF(P29,TODAY(),"MD")&" días"))) -> -
A30: 34 | B30: Chimbote | C30: Ancash | D30: FM | E30: 96.3 | F30: 53 | G30: A.A | H30: CHIMBOTE | I30: 18/11/2025 - Sectoristas - El pastor Omar el día de ayer señalo que la radio se encuentra operativa. | J30: Homologacion de transmisor | K30: ="R - "&A30 -> R - 34 | Q30: =IF(P30="","-", IF(DATEDIF(P30,TODAY(),"Y")=0,"",IF(DATEDIF(P30,TODAY(),"Y")=1,DATEDIF(P30,TODAY(),"Y")&" año con ",DATEDIF(P30,TODAY(),"Y")&" años con "))&IF(DATEDIF(P30,TODAY(),"YM")=0,"",IF(DATEDIF(P30,TODAY(),"YM")=1,DATEDIF(P30,TODAY(),"YM")&" mes y ",DATEDIF(P30,TODAY(),"YM")&" meses y "))&IF(DATEDIF(P30,TODAY(),"MD")=0,"",IF(DATEDIF(P30,TODAY(),"MD")=1,DATEDIF(P30,TODAY(),"MD")&" día",DATEDIF(P30,TODAY(),"MD")&" días"))) -> -
A31: 35 | B31: Chongoyape | C31: Lambayeque | D31: FM | E31: 92.3 | F31: 111 | G31: A.A | H31: CHONGOYAPE | I31: 27/11/2025 - Sectoristas - El dia de hoy el pastor local envia video evidenciando que la radio se encuentra opeartiva. | J31: Revision transmisor | K31: ="R - "&A31 -> R - 35 | L31: Sectoristas | M31: Nivel 1 | Q31: =IF(P31="","-", IF(DATEDIF(P31,TODAY(),"Y")=0,"",IF(DATEDIF(P31,TODAY(),"Y")=1,DATEDIF(P31,TODAY(),"Y")&" año con ",DATEDIF(P31,TODAY(),"Y")&" años con "))&IF(DATEDIF(P31,TODAY(),"YM")=0,"",IF(DATEDIF(P31,TODAY(),"YM")=1,DATEDIF(P31,TODAY(),"YM")&" mes y ",DATEDIF(P31,TODAY(),"YM")&" meses y "))&IF(DATEDIF(P31,TODAY(),"MD")=0,"",IF(DATEDIF(P31,TODAY(),"MD")=1,DATEDIF(P31,TODAY(),"MD")&" día",DATEDIF(P31,TODAY(),"MD")&" días"))) -> -
A32: 37 | B32: Chulucanas | C32: Piura | D32: FM | E32: 95.3 | F32: 62 | G32: A.A | H32: CHULUCANAS | I32: 27/11/2025 - Sectoristas - Con fecha martes 25 de noviembre el pastor local envía evidencia de operatividad a través de video y audio. | J32: Mantenimiento antenas | K32: ="R - "&A32 -> R - 37 | L32: Sectoristas | M32: Nivel 1 | Q32: =IF(P32="","-", IF(DATEDIF(P32,TODAY(),"Y")=0,"",IF(DATEDIF(P32,TODAY(),"Y")=1,DATEDIF(P32,TODAY(),"Y")&" año con ",DATEDIF(P32,TODAY(),"Y")&" años con "))&IF(DATEDIF(P32,TODAY(),"YM")=0,"",IF(DATEDIF(P32,TODAY(),"YM")=1,DATEDIF(P32,TODAY(),"YM")&" mes y ",DATEDIF(P32,TODAY(),"YM")&" meses y "))&IF(DATEDIF(P32,TODAY(),"MD")=0,"",IF(DATEDIF(P32,TODAY(),"MD")=1,DATEDIF(P32,TODAY(),"MD")&" día",DATEDIF(P32,TODAY(),"MD")&" días"))) -> -
A33: 38 | B33: Conchucos | C33: Ancash | D33: VHF | E33: 10 | F33: 53 | G33: A.A | H33: CONCHUCOS | I33: 27/11/2025 - Sectoristas - Con fecha 27 de noviembre 2025 el pastor envia evidencia por video de la operatividad del canal | K33: ="R - "&A33 -> R - 38 | L33: Sectoristas | M33: Nivel 1 | Q33: =IF(P33="","-", IF(DATEDIF(P33,TODAY(),"Y")=0,"",IF(DATEDIF(P33,TODAY(),"Y")=1,DATEDIF(P33,TODAY(),"Y")&" año con ",DATEDIF(P33,TODAY(),"Y")&" años con "))&IF(DATEDIF(P33,TODAY(),"YM")=0,"",IF(DATEDIF(P33,TODAY(),"YM")=1,DATEDIF(P33,TODAY(),"YM")&" mes y ",DATEDIF(P33,TODAY(),"YM")&" meses y "))&IF(DATEDIF(P33,TODAY(),"MD")=0,"",IF(DATEDIF(P33,TODAY(),"MD")=1,DATEDIF(P33,TODAY(),"MD")&" día",DATEDIF(P33,TODAY(),"MD")&" días"))) -> -
A34: 42 | B34: Huacrachuco | C34: Huanuco | D34: VHF | E34: 9 | F34: 81 | G34: A.A | H34: HUACRACHUCO | I34: 1/12/2025 - Sectoristas - Con fecha martes 25 jueves 27 de noviembre y lunes 01 de diciembre se solicitó evidencia de monitoreo, el pastor envió esta evidencia en video el dia de hoy. | K34: ="R - "&A34 -> R - 42 | L34: Sectoristas | M34: Nivel 1 | Q34: =IF(P34="","-", IF(DATEDIF(P34,TODAY(),"Y")=0,"",IF(DATEDIF(P34,TODAY(),"Y")=1,DATEDIF(P34,TODAY(),"Y")&" año con ",DATEDIF(P34,TODAY(),"Y")&" años con "))&IF(DATEDIF(P34,TODAY(),"YM")=0,"",IF(DATEDIF(P34,TODAY(),"YM")=1,DATEDIF(P34,TODAY(),"YM")&" mes y ",DATEDIF(P34,TODAY(),"YM")&" meses y "))&IF(DATEDIF(P34,TODAY(),"MD")=0,"",IF(DATEDIF(P34,TODAY(),"MD")=1,DATEDIF(P34,TODAY(),"MD")&" día",DATEDIF(P34,TODAY(),"MD")&" días"))) -> -
A35: 43 | B35: Huamachuco | C35: La Libertad | D35: FM | E35: 92.5 | F35: 55 | G35: A.A | H35: HUAMACHUCO | I35: 25/11/2025 - Sectoristas - Según información facilitada por el pastor con fecha 19 de noviembre la radio se encuentra con señal al aire | K35: ="R - "&A35 -> R - 43 | L35: Sectoristas | M35: Nivel 1 | Q35: =IF(P35="","-", IF(DATEDIF(P35,TODAY(),"Y")=0,"",IF(DATEDIF(P35,TODAY(),"Y")=1,DATEDIF(P35,TODAY(),"Y")&" año con ",DATEDIF(P35,TODAY(),"Y")&" años con "))&IF(DATEDIF(P35,TODAY(),"YM")=0,"",IF(DATEDIF(P35,TODAY(),"YM")=1,DATEDIF(P35,TODAY(),"YM")&" mes y ",DATEDIF(P35,TODAY(),"YM")&" meses y "))&IF(DATEDIF(P35,TODAY(),"MD")=0,"",IF(DATEDIF(P35,TODAY(),"MD")=1,DATEDIF(P35,TODAY(),"MD")&" día",DATEDIF(P35,TODAY(),"MD")&" días"))) -> -
A36: 47 | B36: Huaraz | C36: Ancash | D36: UHF | E36: 43 | F36: 12 | G36: A.A | H36: HUARAZ | I36: 28/11/2025 - Sectoristas - Con fecha jueves 27 de noviembre el hno Kelion envia video donde se visualiza la señal de tv | K36: ="R - "&A36 -> R - 47 | L36: Sectoristas | M36: Nivel 1 | Q36: =IF(P36="","-", IF(DATEDIF(P36,TODAY(),"Y")=0,"",IF(DATEDIF(P36,TODAY(),"Y")=1,DATEDIF(P36,TODAY(),"Y")&" año con ",DATEDIF(P36,TODAY(),"Y")&" años con "))&IF(DATEDIF(P36,TODAY(),"YM")=0,"",IF(DATEDIF(P36,TODAY(),"YM")=1,DATEDIF(P36,TODAY(),"YM")&" mes y ",DATEDIF(P36,TODAY(),"YM")&" meses y "))&IF(DATEDIF(P36,TODAY(),"MD")=0,"",IF(DATEDIF(P36,TODAY(),"MD")=1,DATEDIF(P36,TODAY(),"MD")&" día",DATEDIF(P36,TODAY(),"MD")&" días"))) -> -
A37: 48 | B37: Huaraz | C37: Ancash | D37: FM | E37: 98.1 | F37: 12 | G37: A.A | H37: HUARAZ | I37: 1/12/2025 - Sectoristas - El pastor Abel Cueto estuvo el dia viernes 28 de noviembre por la localidad verificando operatividad de la radio y canal. Pero como los equipos están bastante deteriorados pero en uso, se enviara presupuesto para adquisición de los mismos en esta primera semana de diciembre. | K37: ="R - "&A37 -> R - 48 | L37: Sectoristas | M37: Nivel 1 | Q37: =IF(P37="","-", IF(DATEDIF(P37,TODAY(),"Y")=0,"",IF(DATEDIF(P37,TODAY(),"Y")=1,DATEDIF(P37,TODAY(),"Y")&" año con ",DATEDIF(P37,TODAY(),"Y")&" años con "))&IF(DATEDIF(P37,TODAY(),"YM")=0,"",IF(DATEDIF(P37,TODAY(),"YM")=1,DATEDIF(P37,TODAY(),"YM")&" mes y ",DATEDIF(P37,TODAY(),"YM")&" meses y "))&IF(DATEDIF(P37,TODAY(),"MD")=0,"",IF(DATEDIF(P37,TODAY(),"MD")=1,DATEDIF(P37,TODAY(),"MD")&" día",DATEDIF(P37,TODAY(),"MD")&" días"))) -> -
A38: 49 | B38: Huari | C38: Ancash | D38: FM | E38: 89.5 | F38: 59 | G38: A.A | H38: HUARI | I38: 27/11/2025 - Sectoristas - El día de ayer 26 de noviembre el pastor local, envio evidencia por audio y video donde se evidencia la operatividad | K38: ="R - "&A38 -> R - 49 | L38: Sectoristas | M38: Nivel 1 | Q38: =IF(P38="","-", IF(DATEDIF(P38,TODAY(),"Y")=0,"",IF(DATEDIF(P38,TODAY(),"Y")=1,DATEDIF(P38,TODAY(),"Y")&" año con ",DATEDIF(P38,TODAY(),"Y")&" años con "))&IF(DATEDIF(P38,TODAY(),"YM")=0,"",IF(DATEDIF(P38,TODAY(),"YM")=1,DATEDIF(P38,TODAY(),"YM")&" mes y ",DATEDIF(P38,TODAY(),"YM")&" meses y "))&IF(DATEDIF(P38,TODAY(),"MD")=0,"",IF(DATEDIF(P38,TODAY(),"MD")=1,DATEDIF(P38,TODAY(),"MD")&" día",DATEDIF(P38,TODAY(),"MD")&" días"))) -> -
A39: 50 | B39: Huarmey | C39: Ancash | D39: VHF | E39: 9 | F39: 95 | G39: A.A | H39: HUARMEY | I39: 9/10/2025 - Sectoristas - Se consulto el día de hoy al pastor Victor Vilela por la operatividad de la radio y tv, señalando que operan normalmente. | K39: ="R - "&A39 -> R - 50 | Q39: =IF(P39="","-", IF(DATEDIF(P39,TODAY(),"Y")=0,"",IF(DATEDIF(P39,TODAY(),"Y")=1,DATEDIF(P39,TODAY(),"Y")&" año con ",DATEDIF(P39,TODAY(),"Y")&" años con "))&IF(DATEDIF(P39,TODAY(),"YM")=0,"",IF(DATEDIF(P39,TODAY(),"YM")=1,DATEDIF(P39,TODAY(),"YM")&" mes y ",DATEDIF(P39,TODAY(),"YM")&" meses y "))&IF(DATEDIF(P39,TODAY(),"MD")=0,"",IF(DATEDIF(P39,TODAY(),"MD")=1,DATEDIF(P39,TODAY(),"MD")&" día",DATEDIF(P39,TODAY(),"MD")&" días"))) -> -
A40: 51 | B40: Huarmey | C40: Ancash | D40: FM | E40: 96.1 | F40: 95 | G40: A.A | H40: HUARMEY | I40: 9/10/2025 - Sectoristas - Se consulto el día de hoy al pastor Victor Vilela por la operatividad de la radio y tv, señalando que operan normalmente. | K40: ="R - "&A40 -> R - 51 | Q40: =IF(P40="","-", IF(DATEDIF(P40,TODAY(),"Y")=0,"",IF(DATEDIF(P40,TODAY(),"Y")=1,DATEDIF(P40,TODAY(),"Y")&" año con ",DATEDIF(P40,TODAY(),"Y")&" años con "))&IF(DATEDIF(P40,TODAY(),"YM")=0,"",IF(DATEDIF(P40,TODAY(),"YM")=1,DATEDIF(P40,TODAY(),"YM")&" mes y ",DATEDIF(P40,TODAY(),"YM")&" meses y "))&IF(DATEDIF(P40,TODAY(),"MD")=0,"",IF(DATEDIF(P40,TODAY(),"MD")=1,DATEDIF(P40,TODAY(),"MD")&" día",DATEDIF(P40,TODAY(),"MD")&" días"))) -> -
...

Sheet CENTRO - CESAR
B1: LOCALIDAD | C1: DPTO. | D1: BANDA | E1: FREC. | F1: PRESBITERIO | G1: ESTADO, | H1: INCIDENCIAS | I1: ÚLTIMA ACTUALIZACIÓN | J1: OBSERVACIONES | K1: ID | L1: RESPONSABLE | M1: NIVEL | N1: PRESUP S/. | O1: PRESUP $ | P1: Fecha F.A | Q1: Tiempo F.A | R1: RENOVACION
A2: 70 | B2: Lima | C2: Lima | D2: UHF | E2: 25 | F2: 1 | G2: A.A | H2: LIMA | I2: 31/10/2025 - Sectoristas - Operativo de acuerdo a lo informado por Hno. Manuel Alvarado | K2: ="C - "&A2 -> C - 70 | Q2: =IF(P2="","-", IF(DATEDIF(P2,TODAY(),"Y")=0,"",IF(DATEDIF(P2,TODAY(),"Y")=1,DATEDIF(P2,TODAY(),"Y")&" año con ",DATEDIF(P2,TODAY(),"Y")&" años con "))&IF(DATEDIF(P2,TODAY(),"YM")=0,"",IF(DATEDIF(P2,TODAY(),"YM")=1,DATEDIF(P2,TODAY(),"YM")&" mes y ",DATEDIF(P2,TODAY(),"YM")&" meses y "))&IF(DATEDIF(P2,TODAY(),"MD")=0,"",IF(DATEDIF(P2,TODAY(),"MD")=1,DATEDIF(P2,TODAY(),"MD")&" día",DATEDIF(P2,TODAY(),"MD")&" días"))) -> -
A3: 71 | B3: Lima | C3: Lima | D3: AM | E3: 660 | F3: 1 | G3: A.A | H3: LIMA | K3: ="C - "&A3 -> C - 71 | Q3: =IF(P3="","-", IF(DATEDIF(P3,TODAY(),"Y")=0,"",IF(DATEDIF(P3,TODAY(),"Y")=1,DATEDIF(P3,TODAY(),"Y")&" año con ",DATEDIF(P3,TODAY(),"Y")&" años con "))&IF(DATEDIF(P3,TODAY(),"YM")=0,"",IF(DATEDIF(P3,TODAY(),"YM")=1,DATEDIF(P3,TODAY(),"YM")&" mes y ",DATEDIF(P3,TODAY(),"YM")&" meses y "))&IF(DATEDIF(P3,TODAY(),"MD")=0,"",IF(DATEDIF(P3,TODAY(),"MD")=1,DATEDIF(P3,TODAY(),"MD")&" día",DATEDIF(P3,TODAY(),"MD")&" días"))) -> -
A4: 72 | B4: Lima | C4: Lima | D4: FM | E4: 100.1 | F4: 1 | G4: A.A | H4: LIMA | I4: 31/10/2025 - Sectoristas - Operativo de acuerdo a lo informado por Hno. Manuel Alvarado | K4: ="C - "&A4 -> C - 72 | Q4: =IF(P4="","-", IF(DATEDIF(P4,TODAY(),"Y")=0,"",IF(DATEDIF(P4,TODAY(),"Y")=1,DATEDIF(P4,TODAY(),"Y")&" año con ",DATEDIF(P4,TODAY(),"Y")&" años con "))&IF(DATEDIF(P4,TODAY(),"YM")=0,"",IF(DATEDIF(P4,TODAY(),"YM")=1,DATEDIF(P4,TODAY(),"YM")&" mes y ",DATEDIF(P4,TODAY(),"YM")&" meses y "))&IF(DATEDIF(P4,TODAY(),"MD")=0,"",IF(DATEDIF(P4,TODAY(),"MD")=1,DATEDIF(P4,TODAY(),"MD")&" día",DATEDIF(P4,TODAY(),"MD")&" días"))) -> -
A5: 73 | B5: Lima | C5: Lima | D5: AM | E5: 1570 | F5: 1 | G5: N.I | H5: LIMA | K5: ="C - "&A5 -> C - 73 | Q5: =IF(P5="","-", IF(DATEDIF(P5,TODAY(),"Y")=0,"",IF(DATEDIF(P5,TODAY(),"Y")=1,DATEDIF(P5,TODAY(),"Y")&" año con ",DATEDIF(P5,TODAY(),"Y")&" años con "))&IF(DATEDIF(P5,TODAY(),"YM")=0,"",IF(DATEDIF(P5,TODAY(),"YM")=1,DATEDIF(P5,TODAY(),"YM")&" mes y ",DATEDIF(P5,TODAY(),"YM")&" meses y "))&IF(DATEDIF(P5,TODAY(),"MD")=0,"",IF(DATEDIF(P5,TODAY(),"MD")=1,DATEDIF(P5,TODAY(),"MD")&" día",DATEDIF(P5,TODAY(),"MD")&" días"))) -> -
A6: 61 | B6: Iquitos | C6: Loreto | D6: UHF | E6: 41 | F6: 5 | G6: N.I | H6: IQUITOS | I6: 14/08/2025 - Sectoristas - A la fecho no se realizo la compra de los equipos | K6: ="C - "&A6 -> C - 61 | Q6: =IF(P6="","-", IF(DATEDIF(P6,TODAY(),"Y")=0,"",IF(DATEDIF(P6,TODAY(),"Y")=1,DATEDIF(P6,TODAY(),"Y")&" año con ",DATEDIF(P6,TODAY(),"Y")&" años con "))&IF(DATEDIF(P6,TODAY(),"YM")=0,"",IF(DATEDIF(P6,TODAY(),"YM")=1,DATEDIF(P6,TODAY(),"YM")&" mes y ",DATEDIF(P6,TODAY(),"YM")&" meses y "))&IF(DATEDIF(P6,TODAY(),"MD")=0,"",IF(DATEDIF(P6,TODAY(),"MD")=1,DATEDIF(P6,TODAY(),"MD")&" día",DATEDIF(P6,TODAY(),"MD")&" días"))) -> -
A7: 122 | B7: Santa Maria de Nanay | C7: Loreto | D7: FM | E7: 94.5 | F7: 5 | G7: F.A | H7: NANAY | I7: 2/12/2025 - Sectoristas - Informar que la estación se encuentra inoperativo de acuerdo a lo informado por el pastor de la zona en esta sema lo estará poniendo operativo | K7: ="C - "&A7 -> C - 122 | L7: Sectoristas | M7: Nivel 1 | Q7: =IF(P7="","-", IF(DATEDIF(P7,TODAY(),"Y")=0,"",IF(DATEDIF(P7,TODAY(),"Y")=1,DATEDIF(P7,TODAY(),"Y")&" año con ",DATEDIF(P7,TODAY(),"Y")&" años con "))&IF(DATEDIF(P7,TODAY(),"YM")=0,"",IF(DATEDIF(P7,TODAY(),"YM")=1,DATEDIF(P7,TODAY(),"YM")&" mes y ",DATEDIF(P7,TODAY(),"YM")&" meses y "))&IF(DATEDIF(P7,TODAY(),"MD")=0,"",IF(DATEDIF(P7,TODAY(),"MD")=1,DATEDIF(P7,TODAY(),"MD")&" día",DATEDIF(P7,TODAY(),"MD")&" días"))) -> -
A8: 132 | B8: Tamshiyacu - Fernando Lores | C8: Loreto | D8: FM | E8: 97.7 | F8: 5 | G8: A.A | H8: TAMSHIYACU | I8: 2/12/2025 - Sectoristas - La estación se encuentra en observación ya que se encuentra fuera del aire por desfiguración del decodificador | K8: ="C - "&A8 -> C - 132 | L8: Sectoristas | M8: Nivel 1 | Q8: =IF(P8="","-", IF(DATEDIF(P8,TODAY(),"Y")=0,"",IF(DATEDIF(P8,TODAY(),"Y")=1,DATEDIF(P8,TODAY(),"Y")&" año con ",DATEDIF(P8,TODAY(),"Y")&" años con "))&IF(DATEDIF(P8,TODAY(),"YM")=0,"",IF(DATEDIF(P8,TODAY(),"YM")=1,DATEDIF(P8,TODAY(),"YM")&" mes y ",DATEDIF(P8,TODAY(),"YM")&" meses y "))&IF(DATEDIF(P8,TODAY(),"MD")=0,"",IF(DATEDIF(P8,TODAY(),"MD")=1,DATEDIF(P8,TODAY(),"MD")&" día",DATEDIF(P8,TODAY(),"MD")&" días"))) -> -
A9: 12 | B9: Ayacucho | C9: Ayacucho | D9: UHF | E9: 39 | F9: 13 | G9: A.A | H9: AYACUCHO | I9: 2/12/2025 - Sectoristas - Operativo de acuerdo a lo informado por el área técnica y las coordinaciones en el WhatsApp | K9: ="C - "&A9 -> C - 12 | L9: Sectoristas | M9: Nivel 1 | Q9: =IF(P9="","-", IF(DATEDIF(P9,TODAY(),"Y")=0,"",IF(DATEDIF(P9,TODAY(),"Y")=1,DATEDIF(P9,TODAY(),"Y")&" año con ",DATEDIF(P9,TODAY(),"Y")&" años con "))&IF(DATEDIF(P9,TODAY(),"YM")=0,"",IF(DATEDIF(P9,TODAY(),"YM")=1,DATEDIF(P9,TODAY(),"YM")&" mes y ",DATEDIF(P9,TODAY(),"YM")&" meses y "))&IF(DATEDIF(P9,TODAY(),"MD")=0,"",IF(DATEDIF(P9,TODAY(),"MD")=1,DATEDIF(P9,TODAY(),"MD")&" día",DATEDIF(P9,TODAY(),"MD")&" días"))) -> -
A10: 13 | B10: Ayacucho | C10: Ayacucho | D10: FM | E10: 93.9 | F10: 13 | G10: A.A | H10: AYACUCHO | I10: 2/12/2025 - Sectoristas - Operativo de acuerdo a lo informado por el área técnica y las coordinaciones en el WhatsApp | K10: ="C - "&A10 -> C - 13 | L10: Sectoristas | M10: Nivel 1 | Q10: =IF(P10="","-", IF(DATEDIF(P10,TODAY(),"Y")=0,"",IF(DATEDIF(P10,TODAY(),"Y")=1,DATEDIF(P10,TODAY(),"Y")&" año con ",DATEDIF(P10,TODAY(),"Y")&" años con "))&IF(DATEDIF(P10,TODAY(),"YM")=0,"",IF(DATEDIF(P10,TODAY(),"YM")=1,DATEDIF(P10,TODAY(),"YM")&" mes y ",DATEDIF(P10,TODAY(),"YM")&" meses y "))&IF(DATEDIF(P10,TODAY(),"MD")=0,"",IF(DATEDIF(P10,TODAY(),"MD")=1,DATEDIF(P10,TODAY(),"MD")&" día",DATEDIF(P10,TODAY(),"MD")&" días"))) -> -
A11: 14 | B11: Ayacucho | C11: Ayacucho | D11: OM | E11: 780 | F11: 13 | G11: A.A | H11: AYACUCHO OM | I11: 2/12/2025 - Sectoristas - Operativo de acuerdo a lo informado por el área técnica y las coordinaciones en el WhatsApp | K11: ="C - "&A11 -> C - 14 | L11: Sectoristas | M11: Nivel 1 | Q11: =IF(P11="","-", IF(DATEDIF(P11,TODAY(),"Y")=0,"",IF(DATEDIF(P11,TODAY(),"Y")=1,DATEDIF(P11,TODAY(),"Y")&" año con ",DATEDIF(P11,TODAY(),"Y")&" años con "))&IF(DATEDIF(P11,TODAY(),"YM")=0,"",IF(DATEDIF(P11,TODAY(),"YM")=1,DATEDIF(P11,TODAY(),"YM")&" mes y ",DATEDIF(P11,TODAY(),"YM")&" meses y "))&IF(DATEDIF(P11,TODAY(),"MD")=0,"",IF(DATEDIF(P11,TODAY(),"MD")=1,DATEDIF(P11,TODAY(),"MD")&" día",DATEDIF(P11,TODAY(),"MD")&" días"))) -> -
A12: 23 | B12: Cangallo | C12: Ayacucho | D12: VHF | E12: 9 | F12: 13 | G12: A.A | H12: CANGALLO | I12: 2/10/2025 - Sectoristas - Operativo de acuerdo a lo informado por el pastor de la zona | K12: ="C - "&A12 -> C - 23 | Q12: =IF(P12="","-", IF(DATEDIF(P12,TODAY(),"Y")=0,"",IF(DATEDIF(P12,TODAY(),"Y")=1,DATEDIF(P12,TODAY(),"Y")&" año con ",DATEDIF(P12,TODAY(),"Y")&" años con "))&IF(DATEDIF(P12,TODAY(),"YM")=0,"",IF(DATEDIF(P12,TODAY(),"YM")=1,DATEDIF(P12,TODAY(),"YM")&" mes y ",DATEDIF(P12,TODAY(),"YM")&" meses y "))&IF(DATEDIF(P12,TODAY(),"MD")=0,"",IF(DATEDIF(P12,TODAY(),"MD")=1,DATEDIF(P12,TODAY(),"MD")&" día",DATEDIF(P12,TODAY(),"MD")&" días"))) -> -
A13: 52 | B13: Huanta | C13: Ayacucho | D13: FM | E13: 101.7 | F13: 13 | G13: A.A | H13: HUANTA | I13: 14/08/2025 - Sectoristas - Operativo de acuerdo a lo informado por el pastor de la zona | K13: ="C - "&A13 -> C - 52 | Q13: =IF(P13="","-", IF(DATEDIF(P13,TODAY(),"Y")=0,"",IF(DATEDIF(P13,TODAY(),"Y")=1,DATEDIF(P13,TODAY(),"Y")&" año con ",DATEDIF(P13,TODAY(),"Y")&" años con "))&IF(DATEDIF(P13,TODAY(),"YM")=0,"",IF(DATEDIF(P13,TODAY(),"YM")=1,DATEDIF(P13,TODAY(),"YM")&" mes y ",DATEDIF(P13,TODAY(),"YM")&" meses y "))&IF(DATEDIF(P13,TODAY(),"MD")=0,"",IF(DATEDIF(P13,TODAY(),"MD")=1,DATEDIF(P13,TODAY(),"MD")&" día",DATEDIF(P13,TODAY(),"MD")&" días"))) -> -
A14: 89 | B14: Pampa Cangallo - Los Morochucos | C14: Ayacucho | D14: FM | E14: 98.1 | F14: 13 | G14: A.A | H14: PAMPA CANGALLO | I14: 23/11/2025 - Ingeniería - Con el apoyo del equipo técnico zonal de Ayacucho, se puso al aire nuevamente la estación. Información facilitada por el hno. Abel Oré. | K14: ="C - "&A14 -> C - 89 | L14: Sectoristas | M14: Nivel 1 | Q14: =IF(P14="","-", IF(DATEDIF(P14,TODAY(),"Y")=0,"",IF(DATEDIF(P14,TODAY(),"Y")=1,DATEDIF(P14,TODAY(),"Y")&" año con ",DATEDIF(P14,TODAY(),"Y")&" años con "))&IF(DATEDIF(P14,TODAY(),"YM")=0,"",IF(DATEDIF(P14,TODAY(),"YM")=1,DATEDIF(P14,TODAY(),"YM")&" mes y ",DATEDIF(P14,TODAY(),"YM")&" meses y "))&IF(DATEDIF(P14,TODAY(),"MD")=0,"",IF(DATEDIF(P14,TODAY(),"MD")=1,DATEDIF(P14,TODAY(),"MD")&" día",DATEDIF(P14,TODAY(),"MD")&" días"))) -> -
A15: 114 | B15: San Miguel | C15: Ayacucho | D15: FM | E15: 93.5 | F15: 13 | G15: A.A | H15: SAN MIGUEL | I15: 3/10/2025 - Sectoristas - Operativo de acuerdo a lo informado por el pastor de la zona | K15: ="C - "&A15 -> C - 114 | Q15: =IF(P15="","-", IF(DATEDIF(P15,TODAY(),"Y")=0,"",IF(DATEDIF(P15,TODAY(),"Y")=1,DATEDIF(P15,TODAY(),"Y")&" año con ",DATEDIF(P15,TODAY(),"Y")&" años con "))&IF(DATEDIF(P15,TODAY(),"YM")=0,"",IF(DATEDIF(P15,TODAY(),"YM")=1,DATEDIF(P15,TODAY(),"YM")&" mes y ",DATEDIF(P15,TODAY(),"YM")&" meses y "))&IF(DATEDIF(P15,TODAY(),"MD")=0,"",IF(DATEDIF(P15,TODAY(),"MD")=1,DATEDIF(P15,TODAY(),"MD")&" día",DATEDIF(P15,TODAY(),"MD")&" días"))) -> -
A16: 115 | B16: San Miguel | C16: Ayacucho | D16: VHF | E16: 9 | F16: 13 | G16: A.A | H16: SAN MIGUEL | I16: 3/10/2025 - Sectoristas - Operativo de acuerdo a lo informado por el pastor de la zona | K16: ="C - "&A16 -> C - 115 | Q16: =IF(P16="","-", IF(DATEDIF(P16,TODAY(),"Y")=0,"",IF(DATEDIF(P16,TODAY(),"Y")=1,DATEDIF(P16,TODAY(),"Y")&" año con ",DATEDIF(P16,TODAY(),"Y")&" años con "))&IF(DATEDIF(P16,TODAY(),"YM")=0,"",IF(DATEDIF(P16,TODAY(),"YM")=1,DATEDIF(P16,TODAY(),"YM")&" mes y ",DATEDIF(P16,TODAY(),"YM")&" meses y "))&IF(DATEDIF(P16,TODAY(),"MD")=0,"",IF(DATEDIF(P16,TODAY(),"MD")=1,DATEDIF(P16,TODAY(),"MD")&" día",DATEDIF(P16,TODAY(),"MD")&" días"))) -> -
A17: 119 | B17: Sancos | C17: Ayacucho | D17: VHF | E17: 6 | F17: 13 | G17: A.A | H17: SANCOS | I17: 3/10/2025 - Sectoristas - Operativo de acuerdo a lo informado por el pastor de la zona (06 Am a 08 Pm) | K17: ="C - "&A17 -> C - 119 | Q17: =IF(P17="","-", IF(DATEDIF(P17,TODAY(),"Y")=0,"",IF(DATEDIF(P17,TODAY(),"Y")=1,DATEDIF(P17,TODAY(),"Y")&" año con ",DATEDIF(P17,TODAY(),"Y")&" años con "))&IF(DATEDIF(P17,TODAY(),"YM")=0,"",IF(DATEDIF(P17,TODAY(),"YM")=1,DATEDIF(P17,TODAY(),"YM")&" mes y ",DATEDIF(P17,TODAY(),"YM")&" meses y "))&IF(DATEDIF(P17,TODAY(),"MD")=0,"",IF(DATEDIF(P17,TODAY(),"MD")=1,DATEDIF(P17,TODAY(),"MD")&" día",DATEDIF(P17,TODAY(),"MD")&" días"))) -> -
A18: 131 | B18: Tambo | C18: Ayacucho | D18: VHF | E18: 7 | F18: 13 | G18: A.A | H18: TAMBO | I18: 3/10/2025 - Sectoristas - Operativo de acuerdo a lo informado por el pastor de zona | K18: ="C - "&A18 -> C - 131 | Q18: =IF(P18="","-", IF(DATEDIF(P18,TODAY(),"Y")=0,"",IF(DATEDIF(P18,TODAY(),"Y")=1,DATEDIF(P18,TODAY(),"Y")&" año con ",DATEDIF(P18,TODAY(),"Y")&" años con "))&IF(DATEDIF(P18,TODAY(),"YM")=0,"",IF(DATEDIF(P18,TODAY(),"YM")=1,DATEDIF(P18,TODAY(),"YM")&" mes y ",DATEDIF(P18,TODAY(),"YM")&" meses y "))&IF(DATEDIF(P18,TODAY(),"MD")=0,"",IF(DATEDIF(P18,TODAY(),"MD")=1,DATEDIF(P18,TODAY(),"MD")&" día",DATEDIF(P18,TODAY(),"MD")&" días"))) -> -
A19: 48 | B19: Huancayo | C19: Junin | D19: UHF | E19: 29 | F19: 15 | G19: A.A | H19: HUANCAYO | I19: 3/10/2025 - Sectoristas - Operativo de acuerdo a lo informado por el presbítero de la zona | K19: ="C - "&A19 -> C - 48 | Q19: =IF(P19="","-", IF(DATEDIF(P19,TODAY(),"Y")=0,"",IF(DATEDIF(P19,TODAY(),"Y")=1,DATEDIF(P19,TODAY(),"Y")&" año con ",DATEDIF(P19,TODAY(),"Y")&" años con "))&IF(DATEDIF(P19,TODAY(),"YM")=0,"",IF(DATEDIF(P19,TODAY(),"YM")=1,DATEDIF(P19,TODAY(),"YM")&" mes y ",DATEDIF(P19,TODAY(),"YM")&" meses y "))&IF(DATEDIF(P19,TODAY(),"MD")=0,"",IF(DATEDIF(P19,TODAY(),"MD")=1,DATEDIF(P19,TODAY(),"MD")&" día",DATEDIF(P19,TODAY(),"MD")&" días"))) -> -
A20: 49 | B20: Huancayo | C20: Junin | D20: AM | E20: 1050 | F20: 15 | G20: A.A | H20: HUANCAYO | I20: 3/10/2025 - Sectoristas - Operativo de acuerdo a lo informado por el presbítero de la zona | K20: ="C - "&A20 -> C - 49 | Q20: =IF(P20="","-", IF(DATEDIF(P20,TODAY(),"Y")=0,"",IF(DATEDIF(P20,TODAY(),"Y")=1,DATEDIF(P20,TODAY(),"Y")&" año con ",DATEDIF(P20,TODAY(),"Y")&" años con "))&IF(DATEDIF(P20,TODAY(),"YM")=0,"",IF(DATEDIF(P20,TODAY(),"YM")=1,DATEDIF(P20,TODAY(),"YM")&" mes y ",DATEDIF(P20,TODAY(),"YM")&" meses y "))&IF(DATEDIF(P20,TODAY(),"MD")=0,"",IF(DATEDIF(P20,TODAY(),"MD")=1,DATEDIF(P20,TODAY(),"MD")&" día",DATEDIF(P20,TODAY(),"MD")&" días"))) -> -
A21: 50 | B21: Huancayo | C21: Junin | D21: FM | E21: 107.7 | F21: 15 | G21: A.A | H21: HUANCAYO FM | K21: ="C - "&A21 -> C - 50 | Q21: =IF(P21="","-", IF(DATEDIF(P21,TODAY(),"Y")=0,"",IF(DATEDIF(P21,TODAY(),"Y")=1,DATEDIF(P21,TODAY(),"Y")&" año con ",DATEDIF(P21,TODAY(),"Y")&" años con "))&IF(DATEDIF(P21,TODAY(),"YM")=0,"",IF(DATEDIF(P21,TODAY(),"YM")=1,DATEDIF(P21,TODAY(),"YM")&" mes y ",DATEDIF(P21,TODAY(),"YM")&" meses y "))&IF(DATEDIF(P21,TODAY(),"MD")=0,"",IF(DATEDIF(P21,TODAY(),"MD")=1,DATEDIF(P21,TODAY(),"MD")&" día",DATEDIF(P21,TODAY(),"MD")&" días"))) -> -
A22: 99 | B22: Pazos | C22: Huancavelica | D22: FM | E22: 94.7 | F22: 15 | G22: A.A | H22: PAZOS | I22: 3/10/2025 - Sectoristas - Operativo de acuerdo a lo informado por el presbítero de la zona | K22: ="C - "&A22 -> C - 99 | Q22: =IF(P22="","-", IF(DATEDIF(P22,TODAY(),"Y")=0,"",IF(DATEDIF(P22,TODAY(),"Y")=1,DATEDIF(P22,TODAY(),"Y")&" año con ",DATEDIF(P22,TODAY(),"Y")&" años con "))&IF(DATEDIF(P22,TODAY(),"YM")=0,"",IF(DATEDIF(P22,TODAY(),"YM")=1,DATEDIF(P22,TODAY(),"YM")&" mes y ",DATEDIF(P22,TODAY(),"YM")&" meses y "))&IF(DATEDIF(P22,TODAY(),"MD")=0,"",IF(DATEDIF(P22,TODAY(),"MD")=1,DATEDIF(P22,TODAY(),"MD")&" día",DATEDIF(P22,TODAY(),"MD")&" días"))) -> -
A23: 78 | B23: Masisea | C23: Ucayali | D23: FM | E23: 99.7 | F23: 17 | G23: A.A | H23: MASISEA | I23: 3/10/2025 - Sectoristas - Operativo de acuerdo a lo informado por el presbítero de la zona | K23: ="C - "&A23 -> C - 78 | Q23: =IF(P23="","-", IF(DATEDIF(P23,TODAY(),"Y")=0,"",IF(DATEDIF(P23,TODAY(),"Y")=1,DATEDIF(P23,TODAY(),"Y")&" año con ",DATEDIF(P23,TODAY(),"Y")&" años con "))&IF(DATEDIF(P23,TODAY(),"YM")=0,"",IF(DATEDIF(P23,TODAY(),"YM")=1,DATEDIF(P23,TODAY(),"YM")&" mes y ",DATEDIF(P23,TODAY(),"YM")&" meses y "))&IF(DATEDIF(P23,TODAY(),"MD")=0,"",IF(DATEDIF(P23,TODAY(),"MD")=1,DATEDIF(P23,TODAY(),"MD")&" día",DATEDIF(P23,TODAY(),"MD")&" días"))) -> -
A24: 105 | B24: Pucallpa | C24: Ucayali | D24: UHF | E24: 39 | F24: 17 | G24: A.A | H24: PUCALLPA | I24: 3/10/2025 - Sectoristas - Operativo de acuerdo a lo informado por el presbítero de la zona | K24: ="C - "&A24 -> C - 105 | Q24: =IF(P24="","-", IF(DATEDIF(P24,TODAY(),"Y")=0,"",IF(DATEDIF(P24,TODAY(),"Y")=1,DATEDIF(P24,TODAY(),"Y")&" año con ",DATEDIF(P24,TODAY(),"Y")&" años con "))&IF(DATEDIF(P24,TODAY(),"YM")=0,"",IF(DATEDIF(P24,TODAY(),"YM")=1,DATEDIF(P24,TODAY(),"YM")&" mes y ",DATEDIF(P24,TODAY(),"YM")&" meses y "))&IF(DATEDIF(P24,TODAY(),"MD")=0,"",IF(DATEDIF(P24,TODAY(),"MD")=1,DATEDIF(P24,TODAY(),"MD")&" día",DATEDIF(P24,TODAY(),"MD")&" días"))) -> -
A25: 106 | B25: Pucallpa - Calleria | C25: Ucayali | D25: FM | E25: 101.3 | F25: 17 | G25: A.A | H25: PUCALLPA | I25: 3/10/2025 - Sectoristas - Operativo de acuerdo a lo informado por el pastor de la zona | K25: ="C - "&A25 -> C - 106 | Q25: =IF(P25="","-", IF(DATEDIF(P25,TODAY(),"Y")=0,"",IF(DATEDIF(P25,TODAY(),"Y")=1,DATEDIF(P25,TODAY(),"Y")&" año con ",DATEDIF(P25,TODAY(),"Y")&" años con "))&IF(DATEDIF(P25,TODAY(),"YM")=0,"",IF(DATEDIF(P25,TODAY(),"YM")=1,DATEDIF(P25,TODAY(),"YM")&" mes y ",DATEDIF(P25,TODAY(),"YM")&" meses y "))&IF(DATEDIF(P25,TODAY(),"MD")=0,"",IF(DATEDIF(P25,TODAY(),"MD")=1,DATEDIF(P25,TODAY(),"MD")&" día",DATEDIF(P25,TODAY(),"MD")&" días"))) -> -
A26: 44 | B26: Huacho | C26: Lima | D26: FM | E26: 89.1 | F26: 20 | G26: A.A | H26: HUACHO | I26: 3/10/2025 - Sectoristas - Operativo de acuerdo a lo informado por el pastor de la zona | K26: ="C - "&A26 -> C - 44 | Q26: =IF(P26="","-", IF(DATEDIF(P26,TODAY(),"Y")=0,"",IF(DATEDIF(P26,TODAY(),"Y")=1,DATEDIF(P26,TODAY(),"Y")&" año con ",DATEDIF(P26,TODAY(),"Y")&" años con "))&IF(DATEDIF(P26,TODAY(),"YM")=0,"",IF(DATEDIF(P26,TODAY(),"YM")=1,DATEDIF(P26,TODAY(),"YM")&" mes y ",DATEDIF(P26,TODAY(),"YM")&" meses y "))&IF(DATEDIF(P26,TODAY(),"MD")=0,"",IF(DATEDIF(P26,TODAY(),"MD")=1,DATEDIF(P26,TODAY(),"MD")&" día",DATEDIF(P26,TODAY(),"MD")&" días"))) -> -
A27: 45 | B27: Huacho - Santa Maria | C27: Lima | D27: AM | E27: 1410 | F27: 20 | G27: N.I | H27: HUACHO OM | I27: 31/10/2025 - Sectoristas - A la fecha la estación sigue inoperativo | K27: ="C - "&A27 -> C - 45 | Q27: =IF(P27="","-", IF(DATEDIF(P27,TODAY(),"Y")=0,"",IF(DATEDIF(P27,TODAY(),"Y")=1,DATEDIF(P27,TODAY(),"Y")&" año con ",DATEDIF(P27,TODAY(),"Y")&" años con "))&IF(DATEDIF(P27,TODAY(),"YM")=0,"",IF(DATEDIF(P27,TODAY(),"YM")=1,DATEDIF(P27,TODAY(),"YM")&" mes y ",DATEDIF(P27,TODAY(),"YM")&" meses y "))&IF(DATEDIF(P27,TODAY(),"MD")=0,"",IF(DATEDIF(P27,TODAY(),"MD")=1,DATEDIF(P27,TODAY(),"MD")&" día",DATEDIF(P27,TODAY(),"MD")&" días"))) -> -
A28: 46 | B28: Huancapallac | C28: Huanuco | D28: FM | E28: 98.1 | F28: 27 | G28: N.I | H28: HUANCAPALLAC | I28: 7/05/2025 - Sectoristas - La estación de radio fue aprobada en diciembre del 2024 teniendo como plazo mínimo para su instalación hasta diciembre del 2025 | K28: ="C - "&A28 -> C - 46 | Q28: =IF(P28="","-", IF(DATEDIF(P28,TODAY(),"Y")=0,"",IF(DATEDIF(P28,TODAY(),"Y")=1,DATEDIF(P28,TODAY(),"Y")&" año con ",DATEDIF(P28,TODAY(),"Y")&" años con "))&IF(DATEDIF(P28,TODAY(),"YM")=0,"",IF(DATEDIF(P28,TODAY(),"YM")=1,DATEDIF(P28,TODAY(),"YM")&" mes y ",DATEDIF(P28,TODAY(),"YM")&" meses y "))&IF(DATEDIF(P28,TODAY(),"MD")=0,"",IF(DATEDIF(P28,TODAY(),"MD")=1,DATEDIF(P28,TODAY(),"MD")&" día",DATEDIF(P28,TODAY(),"MD")&" días"))) -> -
A29: 53 | B29: Huánuco | C29: Huanuco | D29: FM | E29: 103.3 | F29: 27 | G29: A.A | H29: HUÁNUCO | I29: 9/10/2025 - Sectoristas - Operativo de acuerdo a lo informado por el pastor Nolasco Ponciano, de la zona opera las 24 horas del día | K29: ="C - "&A29 -> C - 53 | Q29: =IF(P29="","-", IF(DATEDIF(P29,TODAY(),"Y")=0,"",IF(DATEDIF(P29,TODAY(),"Y")=1,DATEDIF(P29,TODAY(),"Y")&" año con ",DATEDIF(P29,TODAY(),"Y")&" años con "))&IF(DATEDIF(P29,TODAY(),"YM")=0,"",IF(DATEDIF(P29,TODAY(),"YM")=1,DATEDIF(P29,TODAY(),"YM")&" mes y ",DATEDIF(P29,TODAY(),"YM")&" meses y "))&IF(DATEDIF(P29,TODAY(),"MD")=0,"",IF(DATEDIF(P29,TODAY(),"MD")=1,DATEDIF(P29,TODAY(),"MD")&" día",DATEDIF(P29,TODAY(),"MD")&" días"))) -> -
A30: 54 | B30: Huánuco | C30: Huanuco | D30: UHF | E30: 27 | F30: 27 | G30: A.A | H30: HUÁNUCO | I30: 9/10/2025 - Sectoristas - Operativo de acuerdo a lo informado por el pastor Nolasco Ponciano, de la zona opera las 24 horas del día | K30: ="C - "&A30 -> C - 54 | Q30: =IF(P30="","-", IF(DATEDIF(P30,TODAY(),"Y")=0,"",IF(DATEDIF(P30,TODAY(),"Y")=1,DATEDIF(P30,TODAY(),"Y")&" año con ",DATEDIF(P30,TODAY(),"Y")&" años con "))&IF(DATEDIF(P30,TODAY(),"YM")=0,"",IF(DATEDIF(P30,TODAY(),"YM")=1,DATEDIF(P30,TODAY(),"YM")&" mes y ",DATEDIF(P30,TODAY(),"YM")&" meses y "))&IF(DATEDIF(P30,TODAY(),"MD")=0,"",IF(DATEDIF(P30,TODAY(),"MD")=1,DATEDIF(P30,TODAY(),"MD")&" día",DATEDIF(P30,TODAY(),"MD")&" días"))) -> -
A31: 21 | B31: Cachicoto - Monzón | C31: Huanuco | D31: FM | E31: 93.7 | F31: 28 | G31: A.A | H31: CACHICOTO | I31: 9/10/2025 - - Operativo de acuerdo a lo informado por el pastor Nolasco Ponciano, de la zona opera las 24 horas del día | K31: ="C - "&A31 -> C - 21 | Q31: =IF(P31="","-", IF(DATEDIF(P31,TODAY(),"Y")=0,"",IF(DATEDIF(P31,TODAY(),"Y")=1,DATEDIF(P31,TODAY(),"Y")&" año con ",DATEDIF(P31,TODAY(),"Y")&" años con "))&IF(DATEDIF(P31,TODAY(),"YM")=0,"",IF(DATEDIF(P31,TODAY(),"YM")=1,DATEDIF(P31,TODAY(),"YM")&" mes y ",DATEDIF(P31,TODAY(),"YM")&" meses y "))&IF(DATEDIF(P31,TODAY(),"MD")=0,"",IF(DATEDIF(P31,TODAY(),"MD")=1,DATEDIF(P31,TODAY(),"MD")&" día",DATEDIF(P31,TODAY(),"MD")&" días"))) -> -
A32: 30 | B32: Cashapampa-Monzón | C32: Huanuco | D32: FM | E32: 99.1 | F32: 28 | G32: A.A | H32: CASHAPAMPA | I32: 9/10/2025 - Sectoristas - Operativo de acuerdo a lo informado por el pastor Nolasco Ponciano, de la zona opera las 24 horas del día | K32: ="C - "&A32 -> C - 30 | Q32: =IF(P32="","-", IF(DATEDIF(P32,TODAY(),"Y")=0,"",IF(DATEDIF(P32,TODAY(),"Y")=1,DATEDIF(P32,TODAY(),"Y")&" año con ",DATEDIF(P32,TODAY(),"Y")&" años con "))&IF(DATEDIF(P32,TODAY(),"YM")=0,"",IF(DATEDIF(P32,TODAY(),"YM")=1,DATEDIF(P32,TODAY(),"YM")&" mes y ",DATEDIF(P32,TODAY(),"YM")&" meses y "))&IF(DATEDIF(P32,TODAY(),"MD")=0,"",IF(DATEDIF(P32,TODAY(),"MD")=1,DATEDIF(P32,TODAY(),"MD")&" día",DATEDIF(P32,TODAY(),"MD")&" días"))) -> -
A33: 82 | B33: Monzon | C33: Huanuco | D33: FM | E33: 104.7 | F33: 28 | G33: A.A | H33: MONZON | I33: 3/10/2025 - Sectoristas - Operativo de acuerdo a lo informado por el hno Nilo | K33: ="C - "&A33 -> C - 82 | Q33: =IF(P33="","-", IF(DATEDIF(P33,TODAY(),"Y")=0,"",IF(DATEDIF(P33,TODAY(),"Y")=1,DATEDIF(P33,TODAY(),"Y")&" año con ",DATEDIF(P33,TODAY(),"Y")&" años con "))&IF(DATEDIF(P33,TODAY(),"YM")=0,"",IF(DATEDIF(P33,TODAY(),"YM")=1,DATEDIF(P33,TODAY(),"YM")&" mes y ",DATEDIF(P33,TODAY(),"YM")&" meses y "))&IF(DATEDIF(P33,TODAY(),"MD")=0,"",IF(DATEDIF(P33,TODAY(),"MD")=1,DATEDIF(P33,TODAY(),"MD")&" día",DATEDIF(P33,TODAY(),"MD")&" días"))) -> -
A34: 135 | B34: Tingo María - Rupa Rupa | C34: Huanuco | D34: FM | E34: 100.3 | F34: 28 | G34: A.A | H34: TINGO MARÍA | I34: 3/10/2025 - Sectoristas - Operativo de acuerdo a lo informado por el pastor de la zona | K34: ="C - "&A34 -> C - 135 | Q34: =IF(P34="","-", IF(DATEDIF(P34,TODAY(),"Y")=0,"",IF(DATEDIF(P34,TODAY(),"Y")=1,DATEDIF(P34,TODAY(),"Y")&" año con ",DATEDIF(P34,TODAY(),"Y")&" años con "))&IF(DATEDIF(P34,TODAY(),"YM")=0,"",IF(DATEDIF(P34,TODAY(),"YM")=1,DATEDIF(P34,TODAY(),"YM")&" mes y ",DATEDIF(P34,TODAY(),"YM")&" meses y "))&IF(DATEDIF(P34,TODAY(),"MD")=0,"",IF(DATEDIF(P34,TODAY(),"MD")=1,DATEDIF(P34,TODAY(),"MD")&" día",DATEDIF(P34,TODAY(),"MD")&" días"))) -> -
A35: 136 | B35: Tingo María - Rupa Rupa | C35: Huanuco | D35: UHF | E35: 25 | F35: 28 | G35: A.A | H35: TINGO MARÍA | I35: 3/10/2025 - Sectoristas - Operativo de acuerdo a lo informado por el pastor de la zona | K35: ="C - "&A35 -> C - 136 | Q35: =IF(P35="","-", IF(DATEDIF(P35,TODAY(),"Y")=0,"",IF(DATEDIF(P35,TODAY(),"Y")=1,DATEDIF(P35,TODAY(),"Y")&" año con ",DATEDIF(P35,TODAY(),"Y")&" años con "))&IF(DATEDIF(P35,TODAY(),"YM")=0,"",IF(DATEDIF(P35,TODAY(),"YM")=1,DATEDIF(P35,TODAY(),"YM")&" mes y ",DATEDIF(P35,TODAY(),"YM")&" meses y "))&IF(DATEDIF(P35,TODAY(),"MD")=0,"",IF(DATEDIF(P35,TODAY(),"MD")=1,DATEDIF(P35,TODAY(),"MD")&" día",DATEDIF(P35,TODAY(),"MD")&" días"))) -> -
A36: 103 | B36: Pichanaki | C36: Junin | D36: FM | E36: 97.9 | F36: 30 | G36: A.A | H36: PICHANAKI | I36: 23/10/2025 - Sectoristas - Operativo de acuerdo a lo informado por el pastor de la zona | K36: ="C - "&A36 -> C - 103 | Q36: =IF(P36="","-", IF(DATEDIF(P36,TODAY(),"Y")=0,"",IF(DATEDIF(P36,TODAY(),"Y")=1,DATEDIF(P36,TODAY(),"Y")&" año con ",DATEDIF(P36,TODAY(),"Y")&" años con "))&IF(DATEDIF(P36,TODAY(),"YM")=0,"",IF(DATEDIF(P36,TODAY(),"YM")=1,DATEDIF(P36,TODAY(),"YM")&" mes y ",DATEDIF(P36,TODAY(),"YM")&" meses y "))&IF(DATEDIF(P36,TODAY(),"MD")=0,"",IF(DATEDIF(P36,TODAY(),"MD")=1,DATEDIF(P36,TODAY(),"MD")&" día",DATEDIF(P36,TODAY(),"MD")&" días"))) -> -
A37: 127 | B37: Satipo | C37: Junin | D37: VHF | E37: 5 | F37: 30 | G37: A.A | H37: SATIPO | I37: 23/10/2025 - Sectoristas - Operativo de acuerdo a lo informado por el presbítero (24 horas) | K37: ="C - "&A37 -> C - 127 | Q37: =IF(P37="","-", IF(DATEDIF(P37,TODAY(),"Y")=0,"",IF(DATEDIF(P37,TODAY(),"Y")=1,DATEDIF(P37,TODAY(),"Y")&" año con ",DATEDIF(P37,TODAY(),"Y")&" años con "))&IF(DATEDIF(P37,TODAY(),"YM")=0,"",IF(DATEDIF(P37,TODAY(),"YM")=1,DATEDIF(P37,TODAY(),"YM")&" mes y ",DATEDIF(P37,TODAY(),"YM")&" meses y "))&IF(DATEDIF(P37,TODAY(),"MD")=0,"",IF(DATEDIF(P37,TODAY(),"MD")=1,DATEDIF(P37,TODAY(),"MD")&" día",DATEDIF(P37,TODAY(),"MD")&" días"))) -> -
A38: 128 | B38: Satipo | C38: Junin | D38: FM | E38: 101.1 | F38: 30 | G38: A.A | H38: SATIPO | I38: 23/10/2025 - Sectoristas - Operativo de acuerdo a lo informado por el presbítero (24 horas) | K38: ="C - "&A38 -> C - 128 | Q38: =IF(P38="","-", IF(DATEDIF(P38,TODAY(),"Y")=0,"",IF(DATEDIF(P38,TODAY(),"Y")=1,DATEDIF(P38,TODAY(),"Y")&" año con ",DATEDIF(P38,TODAY(),"Y")&" años con "))&IF(DATEDIF(P38,TODAY(),"YM")=0,"",IF(DATEDIF(P38,TODAY(),"YM")=1,DATEDIF(P38,TODAY(),"YM")&" mes y ",DATEDIF(P38,TODAY(),"YM")&" meses y "))&IF(DATEDIF(P38,TODAY(),"MD")=0,"",IF(DATEDIF(P38,TODAY(),"MD")=1,DATEDIF(P38,TODAY(),"MD")&" día",DATEDIF(P38,TODAY(),"MD")&" días"))) -> -
A39: 37 | B39: Codo del Pozuzo | C39: Junin | D39: FM | E39: 97.3 | F39: 32 | G39: A.A | H39: CODO DEL POZUZO | I39: 28/10/2025 - Sectoristas - Operativo de acuerdo a lo informado por el pastor Ps. Hermes responsable de la estación de radio (opera de 04 am a 11 pm) | K39: ="C - "&A39 -> C - 37 | Q39: =IF(P39="","-", IF(DATEDIF(P39,TODAY(),"Y")=0,"",IF(DATEDIF(P39,TODAY(),"Y")=1,DATEDIF(P39,TODAY(),"Y")&" año con ",DATEDIF(P39,TODAY(),"Y")&" años con "))&IF(DATEDIF(P39,TODAY(),"YM")=0,"",IF(DATEDIF(P39,TODAY(),"YM")=1,DATEDIF(P39,TODAY(),"YM")&" mes y ",DATEDIF(P39,TODAY(),"YM")&" meses y "))&IF(DATEDIF(P39,TODAY(),"MD")=0,"",IF(DATEDIF(P39,TODAY(),"MD")=1,DATEDIF(P39,TODAY(),"MD")&" día",DATEDIF(P39,TODAY(),"MD")&" días"))) -> -
A40: 39 | B40: Constitucion | C40: Pasco | D40: FM | E40: 100.3 | F40: 32 | G40: A.A | H40: CONSTITUCIÓN | I40: 28/10/2025 - Sectoristas - Operativo de acuerdo a lo informado por el presbítero | K40: ="C - "&A40 -> C - 39 | Q40: =IF(P40="","-", IF(DATEDIF(P40,TODAY(),"Y")=0,"",IF(DATEDIF(P40,TODAY(),"Y")=1,DATEDIF(P40,TODAY(),"Y")&" año con ",DATEDIF(P40,TODAY(),"Y")&" años con "))&IF(DATEDIF(P40,TODAY(),"YM")=0,"",IF(DATEDIF(P40,TODAY(),"YM")=1,DATEDIF(P40,TODAY(),"YM")&" mes y ",DATEDIF(P40,TODAY(),"YM")&" meses y "))&IF(DATEDIF(P40,TODAY(),"MD")=0,"",IF(DATEDIF(P40,TODAY(),"MD")=1,DATEDIF(P40,TODAY(),"MD")&" día",DATEDIF(P40,TODAY(),"MD")&" días"))) -> -
...

Sheet SUR - ESTER
B1: LOCALIDAD | C1: DPTO. | D1: BANDA | E1: FREC. | F1: PRESBITERIO | G1: ESTADO | H1: INCIDENCIAS | I1: ULTIMA ACTUALIZACION | J1: OBSERVACIONES | K1: ID | L1: RESPONSABLE | M1: NIVEL | N1: PRESUP S/. | O1: PRESUP $ | P1: Fecha F.A | Q1: Tiempo F.A | R1: RENOVACION
A2: 1 | B2: Abancay | C2: Apurimac | D2: FM | E2: 106,7 | F2: 67 | G2: A.A | H2: ABANCAY | I2: 11/11/2025 - Sectoristas - Opera con normalidad / inf. Ps. Juan Carlos Lazaro | K2: ="E - "&A2 -> E - 1 | L2: Sectoristas | M2: Nivel 1 | Q2: =IF(P2="","-", IF(DATEDIF(P2,TODAY(),"Y")=0,"",IF(DATEDIF(P2,TODAY(),"Y")=1,DATEDIF(P2,TODAY(),"Y")&" año con ",DATEDIF(P2,TODAY(),"Y")&" años con "))&IF(DATEDIF(P2,TODAY(),"YM")=0,"",IF(DATEDIF(P2,TODAY(),"YM")=1,DATEDIF(P2,TODAY(),"YM")&" mes y ",DATEDIF(P2,TODAY(),"YM")&" meses y "))&IF(DATEDIF(P2,TODAY(),"MD")=0,"",IF(DATEDIF(P2,TODAY(),"MD")=1,DATEDIF(P2,TODAY(),"MD")&" día",DATEDIF(P2,TODAY(),"MD")&" días"))) -> -
A3: 2 | B3: Abancay - Tamburco | C3: Apurimac | D3: UHF | E3: 33 | F3: 67 | G3: A.A | H3: ABANCAY | I3: 11/11/2025 - Sectoristas - Opera con normalidad / inf. Ps. Juan Carlos Lazaro | K3: ="E - "&A3 -> E - 2 | L3: Sectoristas | M3: Nivel 1 | Q3: =IF(P3="","-", IF(DATEDIF(P3,TODAY(),"Y")=0,"",IF(DATEDIF(P3,TODAY(),"Y")=1,DATEDIF(P3,TODAY(),"Y")&" año con ",DATEDIF(P3,TODAY(),"Y")&" años con "))&IF(DATEDIF(P3,TODAY(),"YM")=0,"",IF(DATEDIF(P3,TODAY(),"YM")=1,DATEDIF(P3,TODAY(),"YM")&" mes y ",DATEDIF(P3,TODAY(),"YM")&" meses y "))&IF(DATEDIF(P3,TODAY(),"MD")=0,"",IF(DATEDIF(P3,TODAY(),"MD")=1,DATEDIF(P3,TODAY(),"MD")&" día",DATEDIF(P3,TODAY(),"MD")&" días"))) -> -
A4: 3 | B4: Acari (Bella Unión) | C4: Arequipa | D4: FM | E4: 101,5 | F4: 65 | G4: A.A | H4: ACARI | I4: 12/11/2025 - Sectoristas - Opera con normalidad / el pastor informo que desea realizar cambio de torre por motivo de oxidacion. | K4: ="E - "&A4 -> E - 3 | Q4: =IF(P4="","-", IF(DATEDIF(P4,TODAY(),"Y")=0,"",IF(DATEDIF(P4,TODAY(),"Y")=1,DATEDIF(P4,TODAY(),"Y")&" año con ",DATEDIF(P4,TODAY(),"Y")&" años con "))&IF(DATEDIF(P4,TODAY(),"YM")=0,"",IF(DATEDIF(P4,TODAY(),"YM")=1,DATEDIF(P4,TODAY(),"YM")&" mes y ",DATEDIF(P4,TODAY(),"YM")&" meses y "))&IF(DATEDIF(P4,TODAY(),"MD")=0,"",IF(DATEDIF(P4,TODAY(),"MD")=1,DATEDIF(P4,TODAY(),"MD")&" día",DATEDIF(P4,TODAY(),"MD")&" días"))) -> -
A5: 4 | B5: Alegria - Las Piedras | C5: Madre de Dios | D5: FM | E5: 97,1 | F5: 34 | G5: A.A | H5: ALEGRIA | I5: 12/11/2025 - Sectoristas - Opera con normalidad / Inf. Ps. Oscar Benavides | K5: ="E - "&A5 -> E - 4 | Q5: =IF(P5="","-", IF(DATEDIF(P5,TODAY(),"Y")=0,"",IF(DATEDIF(P5,TODAY(),"Y")=1,DATEDIF(P5,TODAY(),"Y")&" año con ",DATEDIF(P5,TODAY(),"Y")&" años con "))&IF(DATEDIF(P5,TODAY(),"YM")=0,"",IF(DATEDIF(P5,TODAY(),"YM")=1,DATEDIF(P5,TODAY(),"YM")&" mes y ",DATEDIF(P5,TODAY(),"YM")&" meses y "))&IF(DATEDIF(P5,TODAY(),"MD")=0,"",IF(DATEDIF(P5,TODAY(),"MD")=1,DATEDIF(P5,TODAY(),"MD")&" día",DATEDIF(P5,TODAY(),"MD")&" días"))) -> -
